2019-07-01 08:42:17,754 - root - ERROR - utils  - 152 - BestBuy(https://www.bestbuy.com/site/reviews/astro-gaming-astro-a50-base-station-rf-wireless-over-the-ear-headphones-black/6349969)报错信息：请求失败
Traceback (most recent call last):
  File "C:\Python36-32\lib\site-packages\urllib3\connectionpool.py", line 600, in urlopen
    chunked=chunked)
  File "C:\Python36-32\lib\site-packages\urllib3\connectionpool.py", line 384, in _make_request
    six.raise_from(e, None)
  File "<string>", line 2, in raise_from
  File "C:\Python36-32\lib\site-packages\urllib3\connectionpool.py", line 380, in _make_request
    httplib_response = conn.getresponse()
  File "C:\Python36-32\lib\http\client.py", line 1331, in getresponse
    response.begin()
  File "C:\Python36-32\lib\http\client.py", line 297, in begin
    version, status, reason = self._read_status()
  File "C:\Python36-32\lib\http\client.py", line 266, in _read_status
    raise RemoteDisconnected("Remote end closed connection without"
http.client.RemoteDisconnected: Remote end closed connection without response

During handling of the above exception, another exception occurred:

Traceback (most recent call last):
  File "C:\Python36-32\lib\site-packages\requests\adapters.py", line 449, in send
    timeout=timeout
  File "C:\Python36-32\lib\site-packages\urllib3\connectionpool.py", line 638, in urlopen
    _stacktrace=sys.exc_info()[2])
  File "C:\Python36-32\lib\site-packages\urllib3\util\retry.py", line 368, in increment
    raise six.reraise(type(error), error, _stacktrace)
  File "C:\Python36-32\lib\site-packages\urllib3\packages\six.py", line 685, in reraise
    raise value.with_traceback(tb)
  File "C:\Python36-32\lib\site-packages\urllib3\connectionpool.py", line 600, in urlopen
    chunked=chunked)
  File "C:\Python36-32\lib\site-packages\urllib3\connectionpool.py", line 384, in _make_request
    six.raise_from(e, None)
  File "<string>", line 2, in raise_from
  File "C:\Python36-32\lib\site-packages\urllib3\connectionpool.py", line 380, in _make_request
    httplib_response = conn.getresponse()
  File "C:\Python36-32\lib\http\client.py", line 1331, in getresponse
    response.begin()
  File "C:\Python36-32\lib\http\client.py", line 297, in begin
    version, status, reason = self._read_status()
  File "C:\Python36-32\lib\http\client.py", line 266, in _read_status
    raise RemoteDisconnected("Remote end closed connection without"
urllib3.exceptions.ProtocolError: ('Connection aborted.', RemoteDisconnected('Remote end closed connection without response',))

During handling of the above exception, another exception occurred:

Traceback (most recent call last):
  File "C:/Users/BruceChen/Desktop/Demo/reviews/bestbuy/bestbuy_review.py", line 37, in parse_url
    resp = requests.get(self.url, headers=self.header, params=kw, timeout=60)
  File "C:\Python36-32\lib\site-packages\requests\api.py", line 75, in get
    return request('get', url, params=params, **kwargs)
  File "C:\Python36-32\lib\site-packages\requests\api.py", line 60, in request
    return session.request(method=method, url=url, **kwargs)
  File "C:\Python36-32\lib\site-packages\requests\sessions.py", line 524, in request
    resp = self.send(prep, **send_kwargs)
  File "C:\Python36-32\lib\site-packages\requests\sessions.py", line 659, in send
    history = [resp for resp in gen] if allow_redirects else []
  File "C:\Python36-32\lib\site-packages\requests\sessions.py", line 659, in <listcomp>
    history = [resp for resp in gen] if allow_redirects else []
  File "C:\Python36-32\lib\site-packages\requests\sessions.py", line 238, in resolve_redirects
    **adapter_kwargs
  File "C:\Python36-32\lib\site-packages\requests\sessions.py", line 637, in send
    r = adapter.send(request, **kwargs)
  File "C:\Python36-32\lib\site-packages\requests\adapters.py", line 498, in send
    raise ConnectionError(err, request=request)
requests.exceptions.ConnectionError: ('Connection aborted.', RemoteDisconnected('Remote end closed connection without response',))
