2019-07-08 12:43:11,037 - root - ERROR - utils  - 169 - Amazon(https://www.amazon.com/Razer-Nari-Wireless-Gel-Infused-Cushions/dp/B07G5RKF3W/ref=sr_1_1)报错信息：请求失败
Traceback (most recent call last):
  File "C:\Users\hhh\AppData\Local\Programs\Python\Python37\lib\site-packages\urllib3\connection.py", line 159, in _new_conn
    (self._dns_host, self.port), self.timeout, **extra_kw)
  File "C:\Users\hhh\AppData\Local\Programs\Python\Python37\lib\site-packages\urllib3\util\connection.py", line 80, in create_connection
    raise err
  File "C:\Users\hhh\AppData\Local\Programs\Python\Python37\lib\site-packages\urllib3\util\connection.py", line 70, in create_connection
    sock.connect(sa)
TimeoutError: [WinError 10060] 由于连接方在一段时间后没有正确答复或连接的主机没有反应，连接尝试失败。

During handling of the above exception, another exception occurred:

Traceback (most recent call last):
  File "C:\Users\hhh\AppData\Local\Programs\Python\Python37\lib\site-packages\urllib3\connectionpool.py", line 600, in urlopen
    chunked=chunked)
  File "C:\Users\hhh\AppData\Local\Programs\Python\Python37\lib\site-packages\urllib3\connectionpool.py", line 343, in _make_request
    self._validate_conn(conn)
  File "C:\Users\hhh\AppData\Local\Programs\Python\Python37\lib\site-packages\urllib3\connectionpool.py", line 839, in _validate_conn
    conn.connect()
  File "C:\Users\hhh\AppData\Local\Programs\Python\Python37\lib\site-packages\urllib3\connection.py", line 301, in connect
    conn = self._new_conn()
  File "C:\Users\hhh\AppData\Local\Programs\Python\Python37\lib\site-packages\urllib3\connection.py", line 168, in _new_conn
    self, "Failed to establish a new connection: %s" % e)
urllib3.exceptions.NewConnectionError: <urllib3.connection.VerifiedHTTPSConnection object at 0x000001965E68A630>: Failed to establish a new connection: [WinError 10060] 由于连接方在一段时间后没有正确答复或连接的主机没有反应，连接尝试失败。

During handling of the above exception, another exception occurred:

Traceback (most recent call last):
  File "C:\Users\hhh\AppData\Local\Programs\Python\Python37\lib\site-packages\requests\adapters.py", line 449, in send
    timeout=timeout
  File "C:\Users\hhh\AppData\Local\Programs\Python\Python37\lib\site-packages\urllib3\connectionpool.py", line 638, in urlopen
    _stacktrace=sys.exc_info()[2])
  File "C:\Users\hhh\AppData\Local\Programs\Python\Python37\lib\site-packages\urllib3\util\retry.py", line 398, in increment
    raise MaxRetryError(_pool, url, error or ResponseError(cause))
urllib3.exceptions.MaxRetryError: HTTPSConnectionPool(host='www.amazon.com', port=443): Max retries exceeded with url: /Razer-Nari-Wireless-Gel-Infused-Cushions/product-reviews/B07G5RKF3W/ref=sr_1_1?filterByLanguage=en_US&sortBy=recent (Caused by NewConnectionError('<urllib3.connection.VerifiedHTTPSConnection object at 0x000001965E68A630>: Failed to establish a new connection: [WinError 10060] 由于连接方在一段时间后没有正确答复或连接的主机没有反应，连接尝试失败。'))

During handling of the above exception, another exception occurred:

Traceback (most recent call last):
  File "C:\Users\hhh\Desktop\Demo\reviews\amazon\amazon_review.py", line 232, in run
    review_html = self.parse_url(review_url)
  File "C:\Users\hhh\AppData\Local\Programs\Python\Python37\lib\site-packages\retrying.py", line 49, in wrapped_f
    return Retrying(*dargs, **dkw).call(f, *args, **kw)
  File "C:\Users\hhh\AppData\Local\Programs\Python\Python37\lib\site-packages\retrying.py", line 212, in call
    raise attempt.get()
  File "C:\Users\hhh\AppData\Local\Programs\Python\Python37\lib\site-packages\retrying.py", line 247, in get
    six.reraise(self.value[0], self.value[1], self.value[2])
  File "C:\Users\hhh\AppData\Local\Programs\Python\Python37\lib\site-packages\six.py", line 693, in reraise
    raise value
  File "C:\Users\hhh\AppData\Local\Programs\Python\Python37\lib\site-packages\retrying.py", line 200, in call
    attempt = Attempt(fn(*args, **kwargs), attempt_number, False)
  File "C:\Users\hhh\Desktop\Demo\reviews\amazon\amazon_review.py", line 40, in parse_url
    resp = requests.get(url, headers=self.headers, params=kw, timeout=100)
  File "C:\Users\hhh\AppData\Local\Programs\Python\Python37\lib\site-packages\requests\api.py", line 75, in get
    return request('get', url, params=params, **kwargs)
  File "C:\Users\hhh\AppData\Local\Programs\Python\Python37\lib\site-packages\requests\api.py", line 60, in request
    return session.request(method=method, url=url, **kwargs)
  File "C:\Users\hhh\AppData\Local\Programs\Python\Python37\lib\site-packages\requests\sessions.py", line 533, in request
    resp = self.send(prep, **send_kwargs)
  File "C:\Users\hhh\AppData\Local\Programs\Python\Python37\lib\site-packages\requests\sessions.py", line 646, in send
    r = adapter.send(request, **kwargs)
  File "C:\Users\hhh\AppData\Local\Programs\Python\Python37\lib\site-packages\requests\adapters.py", line 516, in send
    raise ConnectionError(e, request=request)
requests.exceptions.ConnectionError: HTTPSConnectionPool(host='www.amazon.com', port=443): Max retries exceeded with url: /Razer-Nari-Wireless-Gel-Infused-Cushions/product-reviews/B07G5RKF3W/ref=sr_1_1?filterByLanguage=en_US&sortBy=recent (Caused by NewConnectionError('<urllib3.connection.VerifiedHTTPSConnection object at 0x000001965E68A630>: Failed to establish a new connection: [WinError 10060] 由于连接方在一段时间后没有正确答复或连接的主机没有反应，连接尝试失败。'))
