2019-07-05 09:03:23,774 - root - ERROR - utils  - 161 - JD(41014808466)报错信息：数据库保存/更新失败
Traceback (most recent call last):
  File "C:\Users\hhh\Desktop\Demo\reviews\JD\jd_review.py", line 157, in save_data
    c.execute(sql)
cx_Oracle.IntegrityError: ORA-00001: 违反唯一约束条件 (EIP.ECOMMERCE_REVIEW_PIX3)
2019-07-05 09:03:23,788 - root - ERROR - utils  - 161 - JD(41014808466)报错信息：数据库保存/更新失败
Traceback (most recent call last):
  File "C:\Users\hhh\Desktop\Demo\reviews\JD\jd_review.py", line 157, in save_data
    c.execute(sql)
cx_Oracle.IntegrityError: ORA-00001: 违反唯一约束条件 (EIP.ECOMMERCE_REVIEW_PIX3)
2019-07-05 09:03:23,794 - root - ERROR - utils  - 161 - JD(41014808466)报错信息：数据库保存/更新失败
Traceback (most recent call last):
  File "C:\Users\hhh\Desktop\Demo\reviews\JD\jd_review.py", line 157, in save_data
    c.execute(sql)
cx_Oracle.IntegrityError: ORA-00001: 违反唯一约束条件 (EIP.ECOMMERCE_REVIEW_PIX3)
2019-07-05 09:03:23,806 - root - ERROR - utils  - 161 - JD(41014808466)报错信息：数据库保存/更新失败
Traceback (most recent call last):
  File "C:\Users\hhh\Desktop\Demo\reviews\JD\jd_review.py", line 157, in save_data
    c.execute(sql)
cx_Oracle.IntegrityError: ORA-00001: 违反唯一约束条件 (EIP.ECOMMERCE_REVIEW_PIX3)
2019-07-05 09:03:23,815 - root - ERROR - utils  - 161 - JD(41014808466)报错信息：数据库保存/更新失败
Traceback (most recent call last):
  File "C:\Users\hhh\Desktop\Demo\reviews\JD\jd_review.py", line 157, in save_data
    c.execute(sql)
cx_Oracle.IntegrityError: ORA-00001: 违反唯一约束条件 (EIP.ECOMMERCE_REVIEW_PIX3)
2019-07-05 09:03:23,826 - root - ERROR - utils  - 161 - JD(41014808466)报错信息：数据库保存/更新失败
Traceback (most recent call last):
  File "C:\Users\hhh\Desktop\Demo\reviews\JD\jd_review.py", line 157, in save_data
    c.execute(sql)
cx_Oracle.IntegrityError: ORA-00001: 违反唯一约束条件 (EIP.ECOMMERCE_REVIEW_PIX3)
2019-07-05 09:03:23,841 - root - ERROR - utils  - 161 - JD(41014808466)报错信息：数据库保存/更新失败
Traceback (most recent call last):
  File "C:\Users\hhh\Desktop\Demo\reviews\JD\jd_review.py", line 157, in save_data
    c.execute(sql)
cx_Oracle.IntegrityError: ORA-00001: 违反唯一约束条件 (EIP.ECOMMERCE_REVIEW_PIX3)
2019-07-05 09:03:23,851 - root - ERROR - utils  - 161 - JD(41014808466)报错信息：数据库保存/更新失败
Traceback (most recent call last):
  File "C:\Users\hhh\Desktop\Demo\reviews\JD\jd_review.py", line 157, in save_data
    c.execute(sql)
cx_Oracle.IntegrityError: ORA-00001: 违反唯一约束条件 (EIP.ECOMMERCE_REVIEW_PIX3)
2019-07-05 09:03:23,861 - root - ERROR - utils  - 161 - JD(41014808466)报错信息：数据库保存/更新失败
Traceback (most recent call last):
  File "C:\Users\hhh\Desktop\Demo\reviews\JD\jd_review.py", line 157, in save_data
    c.execute(sql)
cx_Oracle.IntegrityError: ORA-00001: 违反唯一约束条件 (EIP.ECOMMERCE_REVIEW_PIX3)
2019-07-05 09:03:23,869 - root - ERROR - utils  - 161 - JD(41014808466)报错信息：数据库保存/更新失败
Traceback (most recent call last):
  File "C:\Users\hhh\Desktop\Demo\reviews\JD\jd_review.py", line 157, in save_data
    c.execute(sql)
cx_Oracle.IntegrityError: ORA-00001: 违反唯一约束条件 (EIP.ECOMMERCE_REVIEW_PIX3)
2019-07-05 09:03:56,583 - root - ERROR - utils  - 161 - https://item.jd.com/100001470134.html(请求失败)报错信息：None
Traceback (most recent call last):
  File "C:\Users\hhh\AppData\Local\Programs\Python\Python37\lib\site-packages\urllib3\connection.py", line 159, in _new_conn
    (self._dns_host, self.port), self.timeout, **extra_kw)
  File "C:\Users\hhh\AppData\Local\Programs\Python\Python37\lib\site-packages\urllib3\util\connection.py", line 80, in create_connection
    raise err
  File "C:\Users\hhh\AppData\Local\Programs\Python\Python37\lib\site-packages\urllib3\util\connection.py", line 70, in create_connection
    sock.connect(sa)
socket.timeout: timed out

During handling of the above exception, another exception occurred:

Traceback (most recent call last):
  File "C:\Users\hhh\AppData\Local\Programs\Python\Python37\lib\site-packages\urllib3\connectionpool.py", line 600, in urlopen
    chunked=chunked)
  File "C:\Users\hhh\AppData\Local\Programs\Python\Python37\lib\site-packages\urllib3\connectionpool.py", line 343, in _make_request
    self._validate_conn(conn)
  File "C:\Users\hhh\AppData\Local\Programs\Python\Python37\lib\site-packages\urllib3\connectionpool.py", line 839, in _validate_conn
    conn.connect()
  File "C:\Users\hhh\AppData\Local\Programs\Python\Python37\lib\site-packages\urllib3\connection.py", line 301, in connect
    conn = self._new_conn()
  File "C:\Users\hhh\AppData\Local\Programs\Python\Python37\lib\site-packages\urllib3\connection.py", line 164, in _new_conn
    (self.host, self.timeout))
urllib3.exceptions.ConnectTimeoutError: (<urllib3.connection.VerifiedHTTPSConnection object at 0x00000191A91EF550>, 'Connection to sclub.jd.com timed out. (connect timeout=20)')

During handling of the above exception, another exception occurred:

Traceback (most recent call last):
  File "C:\Users\hhh\AppData\Local\Programs\Python\Python37\lib\site-packages\requests\adapters.py", line 449, in send
    timeout=timeout
  File "C:\Users\hhh\AppData\Local\Programs\Python\Python37\lib\site-packages\urllib3\connectionpool.py", line 638, in urlopen
    _stacktrace=sys.exc_info()[2])
  File "C:\Users\hhh\AppData\Local\Programs\Python\Python37\lib\site-packages\urllib3\util\retry.py", line 398, in increment
    raise MaxRetryError(_pool, url, error or ResponseError(cause))
urllib3.exceptions.MaxRetryError: HTTPSConnectionPool(host='sclub.jd.com', port=443): Max retries exceeded with url: /comment/productPageComments.action?productId=100001470134&score=0&sortType=6&page=2&pageSize=10&isShadowSku=0&rid=0&fold=1 (Caused by ConnectTimeoutError(<urllib3.connection.VerifiedHTTPSConnection object at 0x00000191A91EF550>, 'Connection to sclub.jd.com timed out. (connect timeout=20)'))

During handling of the above exception, another exception occurred:

Traceback (most recent call last):
  File "C:\Users\hhh\Desktop\Demo\reviews\JD\jd_review.py", line 34, in getHtml
    resp = requests.get(self.url, headers=headers, params=data, timeout=20)
  File "C:\Users\hhh\AppData\Local\Programs\Python\Python37\lib\site-packages\requests\api.py", line 75, in get
    return request('get', url, params=params, **kwargs)
  File "C:\Users\hhh\AppData\Local\Programs\Python\Python37\lib\site-packages\requests\api.py", line 60, in request
    return session.request(method=method, url=url, **kwargs)
  File "C:\Users\hhh\AppData\Local\Programs\Python\Python37\lib\site-packages\requests\sessions.py", line 533, in request
    resp = self.send(prep, **send_kwargs)
  File "C:\Users\hhh\AppData\Local\Programs\Python\Python37\lib\site-packages\requests\sessions.py", line 646, in send
    r = adapter.send(request, **kwargs)
  File "C:\Users\hhh\AppData\Local\Programs\Python\Python37\lib\site-packages\requests\adapters.py", line 504, in send
    raise ConnectTimeout(e, request=request)
requests.exceptions.ConnectTimeout: HTTPSConnectionPool(host='sclub.jd.com', port=443): Max retries exceeded with url: /comment/productPageComments.action?productId=100001470134&score=0&sortType=6&page=2&pageSize=10&isShadowSku=0&rid=0&fold=1 (Caused by ConnectTimeoutError(<urllib3.connection.VerifiedHTTPSConnection object at 0x00000191A91EF550>, 'Connection to sclub.jd.com timed out. (connect timeout=20)'))
2019-07-05 09:04:02,270 - root - ERROR - utils  - 161 - BestBuy(https://www.bestbuy.com/site/reviews/astro-gaming-astro-a50-base-station-rf-wireless-over-the-ear-headphones-black/6349969)报错信息：请求失败
Traceback (most recent call last):
  File "C:\Users\hhh\AppData\Local\Programs\Python\Python37\lib\site-packages\urllib3\connection.py", line 159, in _new_conn
    (self._dns_host, self.port), self.timeout, **extra_kw)
  File "C:\Users\hhh\AppData\Local\Programs\Python\Python37\lib\site-packages\urllib3\util\connection.py", line 80, in create_connection
    raise err
  File "C:\Users\hhh\AppData\Local\Programs\Python\Python37\lib\site-packages\urllib3\util\connection.py", line 70, in create_connection
    sock.connect(sa)
TimeoutError: [WinError 10060] 由于连接方在一段时间后没有正确答复或连接的主机没有反应，连接尝试失败。

During handling of the above exception, another exception occurred:

Traceback (most recent call last):
  File "C:\Users\hhh\AppData\Local\Programs\Python\Python37\lib\site-packages\urllib3\connectionpool.py", line 600, in urlopen
    chunked=chunked)
  File "C:\Users\hhh\AppData\Local\Programs\Python\Python37\lib\site-packages\urllib3\connectionpool.py", line 343, in _make_request
    self._validate_conn(conn)
  File "C:\Users\hhh\AppData\Local\Programs\Python\Python37\lib\site-packages\urllib3\connectionpool.py", line 839, in _validate_conn
    conn.connect()
  File "C:\Users\hhh\AppData\Local\Programs\Python\Python37\lib\site-packages\urllib3\connection.py", line 301, in connect
    conn = self._new_conn()
  File "C:\Users\hhh\AppData\Local\Programs\Python\Python37\lib\site-packages\urllib3\connection.py", line 168, in _new_conn
    self, "Failed to establish a new connection: %s" % e)
urllib3.exceptions.NewConnectionError: <urllib3.connection.VerifiedHTTPSConnection object at 0x00000191A9A59668>: Failed to establish a new connection: [WinError 10060] 由于连接方在一段时间后没有正确答复或连接的主机没有反应，连接尝试失败。

During handling of the above exception, another exception occurred:

Traceback (most recent call last):
  File "C:\Users\hhh\AppData\Local\Programs\Python\Python37\lib\site-packages\requests\adapters.py", line 449, in send
    timeout=timeout
  File "C:\Users\hhh\AppData\Local\Programs\Python\Python37\lib\site-packages\urllib3\connectionpool.py", line 638, in urlopen
    _stacktrace=sys.exc_info()[2])
  File "C:\Users\hhh\AppData\Local\Programs\Python\Python37\lib\site-packages\urllib3\util\retry.py", line 398, in increment
    raise MaxRetryError(_pool, url, error or ResponseError(cause))
urllib3.exceptions.MaxRetryError: HTTPSConnectionPool(host='www.bestbuy.com', port=443): Max retries exceeded with url: /site/reviews/astro-gaming-astro-a50-base-station-rf-wireless-over-the-ear-headphones-black/6349969?page=1&rating=2&sort=MOST_RECENT (Caused by NewConnectionError('<urllib3.connection.VerifiedHTTPSConnection object at 0x00000191A9A59668>: Failed to establish a new connection: [WinError 10060] 由于连接方在一段时间后没有正确答复或连接的主机没有反应，连接尝试失败。'))

During handling of the above exception, another exception occurred:

Traceback (most recent call last):
  File "C:\Users\hhh\Desktop\Demo\reviews\bestbuy\bestbuy_review.py", line 38, in parse_url
    resp = requests.get(self.url, headers=self.header, params=kw, timeout=60)
  File "C:\Users\hhh\AppData\Local\Programs\Python\Python37\lib\site-packages\requests\api.py", line 75, in get
    return request('get', url, params=params, **kwargs)
  File "C:\Users\hhh\AppData\Local\Programs\Python\Python37\lib\site-packages\requests\api.py", line 60, in request
    return session.request(method=method, url=url, **kwargs)
  File "C:\Users\hhh\AppData\Local\Programs\Python\Python37\lib\site-packages\requests\sessions.py", line 533, in request
    resp = self.send(prep, **send_kwargs)
  File "C:\Users\hhh\AppData\Local\Programs\Python\Python37\lib\site-packages\requests\sessions.py", line 646, in send
    r = adapter.send(request, **kwargs)
  File "C:\Users\hhh\AppData\Local\Programs\Python\Python37\lib\site-packages\requests\adapters.py", line 516, in send
    raise ConnectionError(e, request=request)
requests.exceptions.ConnectionError: HTTPSConnectionPool(host='www.bestbuy.com', port=443): Max retries exceeded with url: /site/reviews/astro-gaming-astro-a50-base-station-rf-wireless-over-the-ear-headphones-black/6349969?page=1&rating=2&sort=MOST_RECENT (Caused by NewConnectionError('<urllib3.connection.VerifiedHTTPSConnection object at 0x00000191A9A59668>: Failed to establish a new connection: [WinError 10060] 由于连接方在一段时间后没有正确答复或连接的主机没有反应，连接尝试失败。'))
2019-07-05 09:04:04,024 - root - ERROR - utils  - 161 - Amazon(https://www.amazon.co.jp/Zero-Audio-TWZ-1000-%E5%AE%8C%E5%85%A8%E3%83%AF%E3%82%A4%E3%83%A4%E3%83%AC%E3%82%B9%E3%82%B9%E3%83%86%E3%83%AC%E3%82%AA%E3%83%98%E3%83%83%E3%83%89%E3%83%9B%E3%83%B3/dp/B07N6NRS8Q/ref=sr_1_1)报错信息：请求失败
Traceback (most recent call last):
  File "C:\Users\hhh\AppData\Local\Programs\Python\Python37\lib\site-packages\urllib3\contrib\pyopenssl.py", line 453, in wrap_socket
    cnx.do_handshake()
  File "C:\Users\hhh\AppData\Local\Programs\Python\Python37\lib\site-packages\OpenSSL\SSL.py", line 1915, in do_handshake
    self._raise_ssl_error(self._ssl, result)
  File "C:\Users\hhh\AppData\Local\Programs\Python\Python37\lib\site-packages\OpenSSL\SSL.py", line 1639, in _raise_ssl_error
    raise SysCallError(errno, errorcode.get(errno))
OpenSSL.SSL.SysCallError: (10054, 'WSAECONNRESET')

During handling of the above exception, another exception occurred:

Traceback (most recent call last):
  File "C:\Users\hhh\AppData\Local\Programs\Python\Python37\lib\site-packages\urllib3\connectionpool.py", line 600, in urlopen
    chunked=chunked)
  File "C:\Users\hhh\AppData\Local\Programs\Python\Python37\lib\site-packages\urllib3\connectionpool.py", line 343, in _make_request
    self._validate_conn(conn)
  File "C:\Users\hhh\AppData\Local\Programs\Python\Python37\lib\site-packages\urllib3\connectionpool.py", line 839, in _validate_conn
    conn.connect()
  File "C:\Users\hhh\AppData\Local\Programs\Python\Python37\lib\site-packages\urllib3\connection.py", line 344, in connect
    ssl_context=context)
  File "C:\Users\hhh\AppData\Local\Programs\Python\Python37\lib\site-packages\urllib3\util\ssl_.py", line 344, in ssl_wrap_socket
    return context.wrap_socket(sock, server_hostname=server_hostname)
  File "C:\Users\hhh\AppData\Local\Programs\Python\Python37\lib\site-packages\urllib3\contrib\pyopenssl.py", line 459, in wrap_socket
    raise ssl.SSLError('bad handshake: %r' % e)
ssl.SSLError: ("bad handshake: SysCallError(10054, 'WSAECONNRESET')",)

During handling of the above exception, another exception occurred:

Traceback (most recent call last):
  File "C:\Users\hhh\AppData\Local\Programs\Python\Python37\lib\site-packages\requests\adapters.py", line 449, in send
    timeout=timeout
  File "C:\Users\hhh\AppData\Local\Programs\Python\Python37\lib\site-packages\urllib3\connectionpool.py", line 638, in urlopen
    _stacktrace=sys.exc_info()[2])
  File "C:\Users\hhh\AppData\Local\Programs\Python\Python37\lib\site-packages\urllib3\util\retry.py", line 398, in increment
    raise MaxRetryError(_pool, url, error or ResponseError(cause))
urllib3.exceptions.MaxRetryError: HTTPSConnectionPool(host='www.amazon.co.jp', port=443): Max retries exceeded with url: /Zero-Audio-TWZ-1000-%E5%AE%8C%E5%85%A8%E3%83%AF%E3%82%A4%E3%83%A4%E3%83%AC%E3%82%B9%E3%82%B9%E3%83%86%E3%83%AC%E3%82%AA%E3%83%98%E3%83%83%E3%83%89%E3%83%9B%E3%83%B3/product-reviews/B07N6NRS8Q/ref=sr_1_1?sortBy=recent&language=zh_CN (Caused by SSLError(SSLError("bad handshake: SysCallError(10054, 'WSAECONNRESET')")))

During handling of the above exception, another exception occurred:

Traceback (most recent call last):
  File "C:\Users\hhh\Desktop\Demo\reviews\amazon\amazon_review.py", line 228, in run
    review_html = self.parse_url(review_url)
  File "C:\Users\hhh\AppData\Local\Programs\Python\Python37\lib\site-packages\retrying.py", line 49, in wrapped_f
    return Retrying(*dargs, **dkw).call(f, *args, **kw)
  File "C:\Users\hhh\AppData\Local\Programs\Python\Python37\lib\site-packages\retrying.py", line 212, in call
    raise attempt.get()
  File "C:\Users\hhh\AppData\Local\Programs\Python\Python37\lib\site-packages\retrying.py", line 247, in get
    six.reraise(self.value[0], self.value[1], self.value[2])
  File "C:\Users\hhh\AppData\Local\Programs\Python\Python37\lib\site-packages\six.py", line 693, in reraise
    raise value
  File "C:\Users\hhh\AppData\Local\Programs\Python\Python37\lib\site-packages\retrying.py", line 200, in call
    attempt = Attempt(fn(*args, **kwargs), attempt_number, False)
  File "C:\Users\hhh\Desktop\Demo\reviews\amazon\amazon_review.py", line 38, in parse_url
    resp = requests.get(url, headers=self.headers, params=kw, timeout=100)
  File "C:\Users\hhh\AppData\Local\Programs\Python\Python37\lib\site-packages\requests\api.py", line 75, in get
    return request('get', url, params=params, **kwargs)
  File "C:\Users\hhh\AppData\Local\Programs\Python\Python37\lib\site-packages\requests\api.py", line 60, in request
    return session.request(method=method, url=url, **kwargs)
  File "C:\Users\hhh\AppData\Local\Programs\Python\Python37\lib\site-packages\requests\sessions.py", line 533, in request
    resp = self.send(prep, **send_kwargs)
  File "C:\Users\hhh\AppData\Local\Programs\Python\Python37\lib\site-packages\requests\sessions.py", line 646, in send
    r = adapter.send(request, **kwargs)
  File "C:\Users\hhh\AppData\Local\Programs\Python\Python37\lib\site-packages\requests\adapters.py", line 514, in send
    raise SSLError(e, request=request)
requests.exceptions.SSLError: HTTPSConnectionPool(host='www.amazon.co.jp', port=443): Max retries exceeded with url: /Zero-Audio-TWZ-1000-%E5%AE%8C%E5%85%A8%E3%83%AF%E3%82%A4%E3%83%A4%E3%83%AC%E3%82%B9%E3%82%B9%E3%83%86%E3%83%AC%E3%82%AA%E3%83%98%E3%83%83%E3%83%89%E3%83%9B%E3%83%B3/product-reviews/B07N6NRS8Q/ref=sr_1_1?sortBy=recent&language=zh_CN (Caused by SSLError(SSLError("bad handshake: SysCallError(10054, 'WSAECONNRESET')")))
2019-07-05 09:04:16,591 - root - ERROR - utils  - 161 - https://item.jd.com/100001470134.html(请求失败)报错信息：None
Traceback (most recent call last):
  File "C:\Users\hhh\AppData\Local\Programs\Python\Python37\lib\site-packages\urllib3\connection.py", line 159, in _new_conn
    (self._dns_host, self.port), self.timeout, **extra_kw)
  File "C:\Users\hhh\AppData\Local\Programs\Python\Python37\lib\site-packages\urllib3\util\connection.py", line 80, in create_connection
    raise err
  File "C:\Users\hhh\AppData\Local\Programs\Python\Python37\lib\site-packages\urllib3\util\connection.py", line 70, in create_connection
    sock.connect(sa)
socket.timeout: timed out

During handling of the above exception, another exception occurred:

Traceback (most recent call last):
  File "C:\Users\hhh\AppData\Local\Programs\Python\Python37\lib\site-packages\urllib3\connectionpool.py", line 600, in urlopen
    chunked=chunked)
  File "C:\Users\hhh\AppData\Local\Programs\Python\Python37\lib\site-packages\urllib3\connectionpool.py", line 343, in _make_request
    self._validate_conn(conn)
  File "C:\Users\hhh\AppData\Local\Programs\Python\Python37\lib\site-packages\urllib3\connectionpool.py", line 839, in _validate_conn
    conn.connect()
  File "C:\Users\hhh\AppData\Local\Programs\Python\Python37\lib\site-packages\urllib3\connection.py", line 301, in connect
    conn = self._new_conn()
  File "C:\Users\hhh\AppData\Local\Programs\Python\Python37\lib\site-packages\urllib3\connection.py", line 164, in _new_conn
    (self.host, self.timeout))
urllib3.exceptions.ConnectTimeoutError: (<urllib3.connection.VerifiedHTTPSConnection object at 0x00000191A9A53470>, 'Connection to sclub.jd.com timed out. (connect timeout=20)')

During handling of the above exception, another exception occurred:

Traceback (most recent call last):
  File "C:\Users\hhh\AppData\Local\Programs\Python\Python37\lib\site-packages\requests\adapters.py", line 449, in send
    timeout=timeout
  File "C:\Users\hhh\AppData\Local\Programs\Python\Python37\lib\site-packages\urllib3\connectionpool.py", line 638, in urlopen
    _stacktrace=sys.exc_info()[2])
  File "C:\Users\hhh\AppData\Local\Programs\Python\Python37\lib\site-packages\urllib3\util\retry.py", line 398, in increment
    raise MaxRetryError(_pool, url, error or ResponseError(cause))
urllib3.exceptions.MaxRetryError: HTTPSConnectionPool(host='sclub.jd.com', port=443): Max retries exceeded with url: /comment/productPageComments.action?productId=100001470134&score=0&sortType=6&page=3&pageSize=10&isShadowSku=0&rid=0&fold=1 (Caused by ConnectTimeoutError(<urllib3.connection.VerifiedHTTPSConnection object at 0x00000191A9A53470>, 'Connection to sclub.jd.com timed out. (connect timeout=20)'))

During handling of the above exception, another exception occurred:

Traceback (most recent call last):
  File "C:\Users\hhh\Desktop\Demo\reviews\JD\jd_review.py", line 34, in getHtml
    resp = requests.get(self.url, headers=headers, params=data, timeout=20)
  File "C:\Users\hhh\AppData\Local\Programs\Python\Python37\lib\site-packages\requests\api.py", line 75, in get
    return request('get', url, params=params, **kwargs)
  File "C:\Users\hhh\AppData\Local\Programs\Python\Python37\lib\site-packages\requests\api.py", line 60, in request
    return session.request(method=method, url=url, **kwargs)
  File "C:\Users\hhh\AppData\Local\Programs\Python\Python37\lib\site-packages\requests\sessions.py", line 533, in request
    resp = self.send(prep, **send_kwargs)
  File "C:\Users\hhh\AppData\Local\Programs\Python\Python37\lib\site-packages\requests\sessions.py", line 646, in send
    r = adapter.send(request, **kwargs)
  File "C:\Users\hhh\AppData\Local\Programs\Python\Python37\lib\site-packages\requests\adapters.py", line 504, in send
    raise ConnectTimeout(e, request=request)
requests.exceptions.ConnectTimeout: HTTPSConnectionPool(host='sclub.jd.com', port=443): Max retries exceeded with url: /comment/productPageComments.action?productId=100001470134&score=0&sortType=6&page=3&pageSize=10&isShadowSku=0&rid=0&fold=1 (Caused by ConnectTimeoutError(<urllib3.connection.VerifiedHTTPSConnection object at 0x00000191A9A53470>, 'Connection to sclub.jd.com timed out. (connect timeout=20)'))
2019-07-05 09:04:23,816 - root - ERROR - utils  - 161 - JD(100001470134)报错信息：数据库保存/更新失败
Traceback (most recent call last):
  File "C:\Users\hhh\Desktop\Demo\reviews\JD\jd_review.py", line 157, in save_data
    c.execute(sql)
cx_Oracle.IntegrityError: ORA-00001: 违反唯一约束条件 (EIP.ECOMMERCE_REVIEW_PIX3)
2019-07-05 09:04:23,827 - root - ERROR - utils  - 161 - JD(100001470134)报错信息：数据库保存/更新失败
Traceback (most recent call last):
  File "C:\Users\hhh\Desktop\Demo\reviews\JD\jd_review.py", line 157, in save_data
    c.execute(sql)
cx_Oracle.IntegrityError: ORA-00001: 违反唯一约束条件 (EIP.ECOMMERCE_REVIEW_PIX3)
2019-07-05 09:04:23,833 - root - ERROR - utils  - 161 - JD(100001470134)报错信息：数据库保存/更新失败
Traceback (most recent call last):
  File "C:\Users\hhh\Desktop\Demo\reviews\JD\jd_review.py", line 157, in save_data
    c.execute(sql)
cx_Oracle.IntegrityError: ORA-00001: 违反唯一约束条件 (EIP.ECOMMERCE_REVIEW_PIX3)
2019-07-05 09:04:23,837 - root - ERROR - utils  - 161 - JD(100001470134)报错信息：数据库保存/更新失败
Traceback (most recent call last):
  File "C:\Users\hhh\Desktop\Demo\reviews\JD\jd_review.py", line 157, in save_data
    c.execute(sql)
cx_Oracle.IntegrityError: ORA-00001: 违反唯一约束条件 (EIP.ECOMMERCE_REVIEW_PIX3)
2019-07-05 09:04:23,847 - root - ERROR - utils  - 161 - JD(100001470134)报错信息：数据库保存/更新失败
Traceback (most recent call last):
  File "C:\Users\hhh\Desktop\Demo\reviews\JD\jd_review.py", line 157, in save_data
    c.execute(sql)
cx_Oracle.IntegrityError: ORA-00001: 违反唯一约束条件 (EIP.ECOMMERCE_REVIEW_PIX3)
2019-07-05 09:04:23,855 - root - ERROR - utils  - 161 - JD(100001470134)报错信息：数据库保存/更新失败
Traceback (most recent call last):
  File "C:\Users\hhh\Desktop\Demo\reviews\JD\jd_review.py", line 157, in save_data
    c.execute(sql)
cx_Oracle.IntegrityError: ORA-00001: 违反唯一约束条件 (EIP.ECOMMERCE_REVIEW_PIX3)
2019-07-05 09:04:23,860 - root - ERROR - utils  - 161 - JD(100001470134)报错信息：数据库保存/更新失败
Traceback (most recent call last):
  File "C:\Users\hhh\Desktop\Demo\reviews\JD\jd_review.py", line 157, in save_data
    c.execute(sql)
cx_Oracle.IntegrityError: ORA-00001: 违反唯一约束条件 (EIP.ECOMMERCE_REVIEW_PIX3)
2019-07-05 09:04:23,866 - root - ERROR - utils  - 161 - JD(100001470134)报错信息：数据库保存/更新失败
Traceback (most recent call last):
  File "C:\Users\hhh\Desktop\Demo\reviews\JD\jd_review.py", line 157, in save_data
    c.execute(sql)
cx_Oracle.IntegrityError: ORA-00001: 违反唯一约束条件 (EIP.ECOMMERCE_REVIEW_PIX3)
2019-07-05 09:04:23,872 - root - ERROR - utils  - 161 - JD(100001470134)报错信息：数据库保存/更新失败
Traceback (most recent call last):
  File "C:\Users\hhh\Desktop\Demo\reviews\JD\jd_review.py", line 157, in save_data
    c.execute(sql)
cx_Oracle.IntegrityError: ORA-00001: 违反唯一约束条件 (EIP.ECOMMERCE_REVIEW_PIX3)
2019-07-05 09:04:23,878 - root - ERROR - utils  - 161 - JD(100001470134)报错信息：数据库保存/更新失败
Traceback (most recent call last):
  File "C:\Users\hhh\Desktop\Demo\reviews\JD\jd_review.py", line 157, in save_data
    c.execute(sql)
cx_Oracle.IntegrityError: ORA-00001: 违反唯一约束条件 (EIP.ECOMMERCE_REVIEW_PIX3)
2019-07-05 09:04:23,884 - root - ERROR - utils  - 161 - JD(100001470134)报错信息：数据库保存/更新失败
Traceback (most recent call last):
  File "C:\Users\hhh\Desktop\Demo\reviews\JD\jd_review.py", line 157, in save_data
    c.execute(sql)
cx_Oracle.IntegrityError: ORA-00001: 违反唯一约束条件 (EIP.ECOMMERCE_REVIEW_PIX3)
2019-07-05 09:04:23,889 - root - ERROR - utils  - 161 - JD(100001470134)报错信息：数据库保存/更新失败
Traceback (most recent call last):
  File "C:\Users\hhh\Desktop\Demo\reviews\JD\jd_review.py", line 157, in save_data
    c.execute(sql)
cx_Oracle.IntegrityError: ORA-00001: 违反唯一约束条件 (EIP.ECOMMERCE_REVIEW_PIX3)
2019-07-05 09:04:23,895 - root - ERROR - utils  - 161 - JD(100001470134)报错信息：数据库保存/更新失败
Traceback (most recent call last):
  File "C:\Users\hhh\Desktop\Demo\reviews\JD\jd_review.py", line 157, in save_data
    c.execute(sql)
cx_Oracle.IntegrityError: ORA-00001: 违反唯一约束条件 (EIP.ECOMMERCE_REVIEW_PIX3)
2019-07-05 09:04:23,901 - root - ERROR - utils  - 161 - JD(100001470134)报错信息：数据库保存/更新失败
Traceback (most recent call last):
  File "C:\Users\hhh\Desktop\Demo\reviews\JD\jd_review.py", line 157, in save_data
    c.execute(sql)
cx_Oracle.IntegrityError: ORA-00001: 违反唯一约束条件 (EIP.ECOMMERCE_REVIEW_PIX3)
2019-07-05 09:04:23,906 - root - ERROR - utils  - 161 - JD(100001470134)报错信息：数据库保存/更新失败
Traceback (most recent call last):
  File "C:\Users\hhh\Desktop\Demo\reviews\JD\jd_review.py", line 157, in save_data
    c.execute(sql)
cx_Oracle.IntegrityError: ORA-00001: 违反唯一约束条件 (EIP.ECOMMERCE_REVIEW_PIX3)
2019-07-05 09:04:23,912 - root - ERROR - utils  - 161 - JD(100001470134)报错信息：数据库保存/更新失败
Traceback (most recent call last):
  File "C:\Users\hhh\Desktop\Demo\reviews\JD\jd_review.py", line 157, in save_data
    c.execute(sql)
cx_Oracle.IntegrityError: ORA-00001: 违反唯一约束条件 (EIP.ECOMMERCE_REVIEW_PIX3)
2019-07-05 09:04:23,918 - root - ERROR - utils  - 161 - JD(100001470134)报错信息：数据库保存/更新失败
Traceback (most recent call last):
  File "C:\Users\hhh\Desktop\Demo\reviews\JD\jd_review.py", line 157, in save_data
    c.execute(sql)
cx_Oracle.IntegrityError: ORA-00001: 违反唯一约束条件 (EIP.ECOMMERCE_REVIEW_PIX3)
2019-07-05 09:04:23,930 - root - ERROR - utils  - 161 - JD(100001470134)报错信息：数据库保存/更新失败
Traceback (most recent call last):
  File "C:\Users\hhh\Desktop\Demo\reviews\JD\jd_review.py", line 157, in save_data
    c.execute(sql)
cx_Oracle.IntegrityError: ORA-00001: 违反唯一约束条件 (EIP.ECOMMERCE_REVIEW_PIX3)
2019-07-05 09:04:23,940 - root - ERROR - utils  - 161 - JD(100001470134)报错信息：数据库保存/更新失败
Traceback (most recent call last):
  File "C:\Users\hhh\Desktop\Demo\reviews\JD\jd_review.py", line 157, in save_data
    c.execute(sql)
cx_Oracle.IntegrityError: ORA-00001: 违反唯一约束条件 (EIP.ECOMMERCE_REVIEW_PIX3)
2019-07-05 09:04:23,951 - root - ERROR - utils  - 161 - JD(100001470134)报错信息：数据库保存/更新失败
Traceback (most recent call last):
  File "C:\Users\hhh\Desktop\Demo\reviews\JD\jd_review.py", line 157, in save_data
    c.execute(sql)
cx_Oracle.IntegrityError: ORA-00001: 违反唯一约束条件 (EIP.ECOMMERCE_REVIEW_PIX3)
2019-07-05 09:04:24,594 - root - ERROR - utils  - 161 - JD(34326476497)报错信息：数据库保存/更新失败
Traceback (most recent call last):
  File "C:\Users\hhh\Desktop\Demo\reviews\JD\jd_review.py", line 157, in save_data
    c.execute(sql)
cx_Oracle.IntegrityError: ORA-00001: 违反唯一约束条件 (EIP.ECOMMERCE_REVIEW_PIX3)
2019-07-05 09:04:24,603 - root - ERROR - utils  - 161 - JD(34326476497)报错信息：数据库保存/更新失败
Traceback (most recent call last):
  File "C:\Users\hhh\Desktop\Demo\reviews\JD\jd_review.py", line 157, in save_data
    c.execute(sql)
cx_Oracle.IntegrityError: ORA-00001: 违反唯一约束条件 (EIP.ECOMMERCE_REVIEW_PIX3)
2019-07-05 09:04:24,976 - root - ERROR - utils  - 161 - JD(2245024)报错信息：数据库保存/更新失败
Traceback (most recent call last):
  File "C:\Users\hhh\Desktop\Demo\reviews\JD\jd_review.py", line 157, in save_data
    c.execute(sql)
cx_Oracle.IntegrityError: ORA-00001: 违反唯一约束条件 (EIP.ECOMMERCE_REVIEW_PIX3)
2019-07-05 09:04:24,983 - root - ERROR - utils  - 161 - JD(2245024)报错信息：数据库保存/更新失败
Traceback (most recent call last):
  File "C:\Users\hhh\Desktop\Demo\reviews\JD\jd_review.py", line 157, in save_data
    c.execute(sql)
cx_Oracle.IntegrityError: ORA-00001: 违反唯一约束条件 (EIP.ECOMMERCE_REVIEW_PIX3)
2019-07-05 09:04:24,988 - root - ERROR - utils  - 161 - JD(2245024)报错信息：数据库保存/更新失败
Traceback (most recent call last):
  File "C:\Users\hhh\Desktop\Demo\reviews\JD\jd_review.py", line 157, in save_data
    c.execute(sql)
cx_Oracle.IntegrityError: ORA-00001: 违反唯一约束条件 (EIP.ECOMMERCE_REVIEW_PIX3)
2019-07-05 09:04:24,994 - root - ERROR - utils  - 161 - JD(2245024)报错信息：数据库保存/更新失败
Traceback (most recent call last):
  File "C:\Users\hhh\Desktop\Demo\reviews\JD\jd_review.py", line 157, in save_data
    c.execute(sql)
cx_Oracle.IntegrityError: ORA-00001: 违反唯一约束条件 (EIP.ECOMMERCE_REVIEW_PIX3)
2019-07-05 09:04:24,998 - root - ERROR - utils  - 161 - JD(2245024)报错信息：数据库保存/更新失败
Traceback (most recent call last):
  File "C:\Users\hhh\Desktop\Demo\reviews\JD\jd_review.py", line 157, in save_data
    c.execute(sql)
cx_Oracle.IntegrityError: ORA-00001: 违反唯一约束条件 (EIP.ECOMMERCE_REVIEW_PIX3)
2019-07-05 09:04:25,003 - root - ERROR - utils  - 161 - JD(2245024)报错信息：数据库保存/更新失败
Traceback (most recent call last):
  File "C:\Users\hhh\Desktop\Demo\reviews\JD\jd_review.py", line 157, in save_data
    c.execute(sql)
cx_Oracle.IntegrityError: ORA-00001: 违反唯一约束条件 (EIP.ECOMMERCE_REVIEW_PIX3)
2019-07-05 09:04:48,690 - root - ERROR - utils  - 161 - https://item.jd.com/46066831853.html(请求失败)报错信息：None
Traceback (most recent call last):
  File "C:\Users\hhh\AppData\Local\Programs\Python\Python37\lib\site-packages\urllib3\connection.py", line 159, in _new_conn
    (self._dns_host, self.port), self.timeout, **extra_kw)
  File "C:\Users\hhh\AppData\Local\Programs\Python\Python37\lib\site-packages\urllib3\util\connection.py", line 80, in create_connection
    raise err
  File "C:\Users\hhh\AppData\Local\Programs\Python\Python37\lib\site-packages\urllib3\util\connection.py", line 70, in create_connection
    sock.connect(sa)
socket.timeout: timed out

During handling of the above exception, another exception occurred:

Traceback (most recent call last):
  File "C:\Users\hhh\AppData\Local\Programs\Python\Python37\lib\site-packages\urllib3\connectionpool.py", line 600, in urlopen
    chunked=chunked)
  File "C:\Users\hhh\AppData\Local\Programs\Python\Python37\lib\site-packages\urllib3\connectionpool.py", line 343, in _make_request
    self._validate_conn(conn)
  File "C:\Users\hhh\AppData\Local\Programs\Python\Python37\lib\site-packages\urllib3\connectionpool.py", line 839, in _validate_conn
    conn.connect()
  File "C:\Users\hhh\AppData\Local\Programs\Python\Python37\lib\site-packages\urllib3\connection.py", line 301, in connect
    conn = self._new_conn()
  File "C:\Users\hhh\AppData\Local\Programs\Python\Python37\lib\site-packages\urllib3\connection.py", line 164, in _new_conn
    (self.host, self.timeout))
urllib3.exceptions.ConnectTimeoutError: (<urllib3.connection.VerifiedHTTPSConnection object at 0x00000191A9A713C8>, 'Connection to sclub.jd.com timed out. (connect timeout=20)')

During handling of the above exception, another exception occurred:

Traceback (most recent call last):
  File "C:\Users\hhh\AppData\Local\Programs\Python\Python37\lib\site-packages\requests\adapters.py", line 449, in send
    timeout=timeout
  File "C:\Users\hhh\AppData\Local\Programs\Python\Python37\lib\site-packages\urllib3\connectionpool.py", line 638, in urlopen
    _stacktrace=sys.exc_info()[2])
  File "C:\Users\hhh\AppData\Local\Programs\Python\Python37\lib\site-packages\urllib3\util\retry.py", line 398, in increment
    raise MaxRetryError(_pool, url, error or ResponseError(cause))
urllib3.exceptions.MaxRetryError: HTTPSConnectionPool(host='sclub.jd.com', port=443): Max retries exceeded with url: /comment/productPageComments.action?productId=46066831853&score=0&sortType=6&page=0&pageSize=10&isShadowSku=0&rid=0&fold=1 (Caused by ConnectTimeoutError(<urllib3.connection.VerifiedHTTPSConnection object at 0x00000191A9A713C8>, 'Connection to sclub.jd.com timed out. (connect timeout=20)'))

During handling of the above exception, another exception occurred:

Traceback (most recent call last):
  File "C:\Users\hhh\Desktop\Demo\reviews\JD\jd_review.py", line 34, in getHtml
    resp = requests.get(self.url, headers=headers, params=data, timeout=20)
  File "C:\Users\hhh\AppData\Local\Programs\Python\Python37\lib\site-packages\requests\api.py", line 75, in get
    return request('get', url, params=params, **kwargs)
  File "C:\Users\hhh\AppData\Local\Programs\Python\Python37\lib\site-packages\requests\api.py", line 60, in request
    return session.request(method=method, url=url, **kwargs)
  File "C:\Users\hhh\AppData\Local\Programs\Python\Python37\lib\site-packages\requests\sessions.py", line 533, in request
    resp = self.send(prep, **send_kwargs)
  File "C:\Users\hhh\AppData\Local\Programs\Python\Python37\lib\site-packages\requests\sessions.py", line 646, in send
    r = adapter.send(request, **kwargs)
  File "C:\Users\hhh\AppData\Local\Programs\Python\Python37\lib\site-packages\requests\adapters.py", line 504, in send
    raise ConnectTimeout(e, request=request)
requests.exceptions.ConnectTimeout: HTTPSConnectionPool(host='sclub.jd.com', port=443): Max retries exceeded with url: /comment/productPageComments.action?productId=46066831853&score=0&sortType=6&page=0&pageSize=10&isShadowSku=0&rid=0&fold=1 (Caused by ConnectTimeoutError(<urllib3.connection.VerifiedHTTPSConnection object at 0x00000191A9A713C8>, 'Connection to sclub.jd.com timed out. (connect timeout=20)'))
2019-07-05 09:05:04,487 - root - ERROR - utils  - 161 - https://item.jd.com/100001667527.html(请求失败)报错信息：None
Traceback (most recent call last):
  File "C:\Users\hhh\AppData\Local\Programs\Python\Python37\lib\site-packages\urllib3\connection.py", line 159, in _new_conn
    (self._dns_host, self.port), self.timeout, **extra_kw)
  File "C:\Users\hhh\AppData\Local\Programs\Python\Python37\lib\site-packages\urllib3\util\connection.py", line 57, in create_connection
    for res in socket.getaddrinfo(host, port, family, socket.SOCK_STREAM):
  File "C:\Users\hhh\AppData\Local\Programs\Python\Python37\lib\socket.py", line 748, in getaddrinfo
    for res in _socket.getaddrinfo(host, port, family, type, proto, flags):
socket.gaierror: [Errno 11001] getaddrinfo failed

During handling of the above exception, another exception occurred:

Traceback (most recent call last):
  File "C:\Users\hhh\AppData\Local\Programs\Python\Python37\lib\site-packages\urllib3\connectionpool.py", line 600, in urlopen
    chunked=chunked)
  File "C:\Users\hhh\AppData\Local\Programs\Python\Python37\lib\site-packages\urllib3\connectionpool.py", line 343, in _make_request
    self._validate_conn(conn)
  File "C:\Users\hhh\AppData\Local\Programs\Python\Python37\lib\site-packages\urllib3\connectionpool.py", line 839, in _validate_conn
    conn.connect()
  File "C:\Users\hhh\AppData\Local\Programs\Python\Python37\lib\site-packages\urllib3\connection.py", line 301, in connect
    conn = self._new_conn()
  File "C:\Users\hhh\AppData\Local\Programs\Python\Python37\lib\site-packages\urllib3\connection.py", line 168, in _new_conn
    self, "Failed to establish a new connection: %s" % e)
urllib3.exceptions.NewConnectionError: <urllib3.connection.VerifiedHTTPSConnection object at 0x00000191AAF49898>: Failed to establish a new connection: [Errno 11001] getaddrinfo failed

During handling of the above exception, another exception occurred:

Traceback (most recent call last):
  File "C:\Users\hhh\AppData\Local\Programs\Python\Python37\lib\site-packages\requests\adapters.py", line 449, in send
    timeout=timeout
  File "C:\Users\hhh\AppData\Local\Programs\Python\Python37\lib\site-packages\urllib3\connectionpool.py", line 638, in urlopen
    _stacktrace=sys.exc_info()[2])
  File "C:\Users\hhh\AppData\Local\Programs\Python\Python37\lib\site-packages\urllib3\util\retry.py", line 398, in increment
    raise MaxRetryError(_pool, url, error or ResponseError(cause))
urllib3.exceptions.MaxRetryError: HTTPSConnectionPool(host='sclub.jd.com', port=443): Max retries exceeded with url: /comment/productPageComments.action?productId=100001667527&score=0&sortType=6&page=0&pageSize=10&isShadowSku=0&rid=0&fold=1 (Caused by NewConnectionError('<urllib3.connection.VerifiedHTTPSConnection object at 0x00000191AAF49898>: Failed to establish a new connection: [Errno 11001] getaddrinfo failed'))

During handling of the above exception, another exception occurred:

Traceback (most recent call last):
  File "C:\Users\hhh\Desktop\Demo\reviews\JD\jd_review.py", line 34, in getHtml
    resp = requests.get(self.url, headers=headers, params=data, timeout=20)
  File "C:\Users\hhh\AppData\Local\Programs\Python\Python37\lib\site-packages\requests\api.py", line 75, in get
    return request('get', url, params=params, **kwargs)
  File "C:\Users\hhh\AppData\Local\Programs\Python\Python37\lib\site-packages\requests\api.py", line 60, in request
    return session.request(method=method, url=url, **kwargs)
  File "C:\Users\hhh\AppData\Local\Programs\Python\Python37\lib\site-packages\requests\sessions.py", line 533, in request
    resp = self.send(prep, **send_kwargs)
  File "C:\Users\hhh\AppData\Local\Programs\Python\Python37\lib\site-packages\requests\sessions.py", line 646, in send
    r = adapter.send(request, **kwargs)
  File "C:\Users\hhh\AppData\Local\Programs\Python\Python37\lib\site-packages\requests\adapters.py", line 516, in send
    raise ConnectionError(e, request=request)
requests.exceptions.ConnectionError: HTTPSConnectionPool(host='sclub.jd.com', port=443): Max retries exceeded with url: /comment/productPageComments.action?productId=100001667527&score=0&sortType=6&page=0&pageSize=10&isShadowSku=0&rid=0&fold=1 (Caused by NewConnectionError('<urllib3.connection.VerifiedHTTPSConnection object at 0x00000191AAF49898>: Failed to establish a new connection: [Errno 11001] getaddrinfo failed'))
2019-07-05 09:05:04,493 - root - ERROR - utils  - 161 - Amazon(https://www.amazon.com/Zolo-Z2000-Liberty-Wireless-Headphones/dp/B075JBP2P7/ref=sr_1_2)报错信息：请求失败
Traceback (most recent call last):
  File "C:\Users\hhh\AppData\Local\Programs\Python\Python37\lib\site-packages\urllib3\connection.py", line 159, in _new_conn
    (self._dns_host, self.port), self.timeout, **extra_kw)
  File "C:\Users\hhh\AppData\Local\Programs\Python\Python37\lib\site-packages\urllib3\util\connection.py", line 57, in create_connection
    for res in socket.getaddrinfo(host, port, family, socket.SOCK_STREAM):
  File "C:\Users\hhh\AppData\Local\Programs\Python\Python37\lib\socket.py", line 748, in getaddrinfo
    for res in _socket.getaddrinfo(host, port, family, type, proto, flags):
socket.gaierror: [Errno 11001] getaddrinfo failed

During handling of the above exception, another exception occurred:

Traceback (most recent call last):
  File "C:\Users\hhh\AppData\Local\Programs\Python\Python37\lib\site-packages\urllib3\connectionpool.py", line 600, in urlopen
    chunked=chunked)
  File "C:\Users\hhh\AppData\Local\Programs\Python\Python37\lib\site-packages\urllib3\connectionpool.py", line 343, in _make_request
    self._validate_conn(conn)
  File "C:\Users\hhh\AppData\Local\Programs\Python\Python37\lib\site-packages\urllib3\connectionpool.py", line 839, in _validate_conn
    conn.connect()
  File "C:\Users\hhh\AppData\Local\Programs\Python\Python37\lib\site-packages\urllib3\connection.py", line 301, in connect
    conn = self._new_conn()
  File "C:\Users\hhh\AppData\Local\Programs\Python\Python37\lib\site-packages\urllib3\connection.py", line 168, in _new_conn
    self, "Failed to establish a new connection: %s" % e)
urllib3.exceptions.NewConnectionError: <urllib3.connection.VerifiedHTTPSConnection object at 0x00000191AAF49F98>: Failed to establish a new connection: [Errno 11001] getaddrinfo failed

During handling of the above exception, another exception occurred:

Traceback (most recent call last):
  File "C:\Users\hhh\AppData\Local\Programs\Python\Python37\lib\site-packages\requests\adapters.py", line 449, in send
    timeout=timeout
  File "C:\Users\hhh\AppData\Local\Programs\Python\Python37\lib\site-packages\urllib3\connectionpool.py", line 638, in urlopen
    _stacktrace=sys.exc_info()[2])
  File "C:\Users\hhh\AppData\Local\Programs\Python\Python37\lib\site-packages\urllib3\util\retry.py", line 398, in increment
    raise MaxRetryError(_pool, url, error or ResponseError(cause))
urllib3.exceptions.MaxRetryError: HTTPSConnectionPool(host='www.amazon.com', port=443): Max retries exceeded with url: /Zolo-Z2000-Liberty-Wireless-Headphones/product-reviews/B075JBP2P7/ref=sr_1_2?filterByLanguage=en_US&sortBy=recent (Caused by NewConnectionError('<urllib3.connection.VerifiedHTTPSConnection object at 0x00000191AAF49F98>: Failed to establish a new connection: [Errno 11001] getaddrinfo failed'))

During handling of the above exception, another exception occurred:

Traceback (most recent call last):
  File "C:\Users\hhh\Desktop\Demo\reviews\amazon\amazon_review.py", line 228, in run
    review_html = self.parse_url(review_url)
  File "C:\Users\hhh\AppData\Local\Programs\Python\Python37\lib\site-packages\retrying.py", line 49, in wrapped_f
    return Retrying(*dargs, **dkw).call(f, *args, **kw)
  File "C:\Users\hhh\AppData\Local\Programs\Python\Python37\lib\site-packages\retrying.py", line 212, in call
    raise attempt.get()
  File "C:\Users\hhh\AppData\Local\Programs\Python\Python37\lib\site-packages\retrying.py", line 247, in get
    six.reraise(self.value[0], self.value[1], self.value[2])
  File "C:\Users\hhh\AppData\Local\Programs\Python\Python37\lib\site-packages\six.py", line 693, in reraise
    raise value
  File "C:\Users\hhh\AppData\Local\Programs\Python\Python37\lib\site-packages\retrying.py", line 200, in call
    attempt = Attempt(fn(*args, **kwargs), attempt_number, False)
  File "C:\Users\hhh\Desktop\Demo\reviews\amazon\amazon_review.py", line 38, in parse_url
    resp = requests.get(url, headers=self.headers, params=kw, timeout=100)
  File "C:\Users\hhh\AppData\Local\Programs\Python\Python37\lib\site-packages\requests\api.py", line 75, in get
    return request('get', url, params=params, **kwargs)
  File "C:\Users\hhh\AppData\Local\Programs\Python\Python37\lib\site-packages\requests\api.py", line 60, in request
    return session.request(method=method, url=url, **kwargs)
  File "C:\Users\hhh\AppData\Local\Programs\Python\Python37\lib\site-packages\requests\sessions.py", line 533, in request
    resp = self.send(prep, **send_kwargs)
  File "C:\Users\hhh\AppData\Local\Programs\Python\Python37\lib\site-packages\requests\sessions.py", line 646, in send
    r = adapter.send(request, **kwargs)
  File "C:\Users\hhh\AppData\Local\Programs\Python\Python37\lib\site-packages\requests\adapters.py", line 516, in send
    raise ConnectionError(e, request=request)
requests.exceptions.ConnectionError: HTTPSConnectionPool(host='www.amazon.com', port=443): Max retries exceeded with url: /Zolo-Z2000-Liberty-Wireless-Headphones/product-reviews/B075JBP2P7/ref=sr_1_2?filterByLanguage=en_US&sortBy=recent (Caused by NewConnectionError('<urllib3.connection.VerifiedHTTPSConnection object at 0x00000191AAF49F98>: Failed to establish a new connection: [Errno 11001] getaddrinfo failed'))
2019-07-05 09:05:04,493 - root - ERROR - utils  - 161 - https://item.jd.com/100002361195.html(请求失败)报错信息：None
Traceback (most recent call last):
  File "C:\Users\hhh\AppData\Local\Programs\Python\Python37\lib\site-packages\urllib3\connection.py", line 159, in _new_conn
    (self._dns_host, self.port), self.timeout, **extra_kw)
  File "C:\Users\hhh\AppData\Local\Programs\Python\Python37\lib\site-packages\urllib3\util\connection.py", line 57, in create_connection
    for res in socket.getaddrinfo(host, port, family, socket.SOCK_STREAM):
  File "C:\Users\hhh\AppData\Local\Programs\Python\Python37\lib\socket.py", line 748, in getaddrinfo
    for res in _socket.getaddrinfo(host, port, family, type, proto, flags):
socket.gaierror: [Errno 11001] getaddrinfo failed

During handling of the above exception, another exception occurred:

Traceback (most recent call last):
  File "C:\Users\hhh\AppData\Local\Programs\Python\Python37\lib\site-packages\urllib3\connectionpool.py", line 600, in urlopen
    chunked=chunked)
  File "C:\Users\hhh\AppData\Local\Programs\Python\Python37\lib\site-packages\urllib3\connectionpool.py", line 343, in _make_request
    self._validate_conn(conn)
  File "C:\Users\hhh\AppData\Local\Programs\Python\Python37\lib\site-packages\urllib3\connectionpool.py", line 839, in _validate_conn
    conn.connect()
  File "C:\Users\hhh\AppData\Local\Programs\Python\Python37\lib\site-packages\urllib3\connection.py", line 301, in connect
    conn = self._new_conn()
  File "C:\Users\hhh\AppData\Local\Programs\Python\Python37\lib\site-packages\urllib3\connection.py", line 168, in _new_conn
    self, "Failed to establish a new connection: %s" % e)
urllib3.exceptions.NewConnectionError: <urllib3.connection.VerifiedHTTPSConnection object at 0x00000191AAF3F358>: Failed to establish a new connection: [Errno 11001] getaddrinfo failed

During handling of the above exception, another exception occurred:

Traceback (most recent call last):
  File "C:\Users\hhh\AppData\Local\Programs\Python\Python37\lib\site-packages\requests\adapters.py", line 449, in send
    timeout=timeout
  File "C:\Users\hhh\AppData\Local\Programs\Python\Python37\lib\site-packages\urllib3\connectionpool.py", line 638, in urlopen
    _stacktrace=sys.exc_info()[2])
  File "C:\Users\hhh\AppData\Local\Programs\Python\Python37\lib\site-packages\urllib3\util\retry.py", line 398, in increment
    raise MaxRetryError(_pool, url, error or ResponseError(cause))
urllib3.exceptions.MaxRetryError: HTTPSConnectionPool(host='sclub.jd.com', port=443): Max retries exceeded with url: /comment/productPageComments.action?productId=100002361195&score=0&sortType=6&page=0&pageSize=10&isShadowSku=0&rid=0&fold=1 (Caused by NewConnectionError('<urllib3.connection.VerifiedHTTPSConnection object at 0x00000191AAF3F358>: Failed to establish a new connection: [Errno 11001] getaddrinfo failed'))

During handling of the above exception, another exception occurred:

Traceback (most recent call last):
  File "C:\Users\hhh\Desktop\Demo\reviews\JD\jd_review.py", line 34, in getHtml
    resp = requests.get(self.url, headers=headers, params=data, timeout=20)
  File "C:\Users\hhh\AppData\Local\Programs\Python\Python37\lib\site-packages\requests\api.py", line 75, in get
    return request('get', url, params=params, **kwargs)
  File "C:\Users\hhh\AppData\Local\Programs\Python\Python37\lib\site-packages\requests\api.py", line 60, in request
    return session.request(method=method, url=url, **kwargs)
  File "C:\Users\hhh\AppData\Local\Programs\Python\Python37\lib\site-packages\requests\sessions.py", line 533, in request
    resp = self.send(prep, **send_kwargs)
  File "C:\Users\hhh\AppData\Local\Programs\Python\Python37\lib\site-packages\requests\sessions.py", line 646, in send
    r = adapter.send(request, **kwargs)
  File "C:\Users\hhh\AppData\Local\Programs\Python\Python37\lib\site-packages\requests\adapters.py", line 516, in send
    raise ConnectionError(e, request=request)
requests.exceptions.ConnectionError: HTTPSConnectionPool(host='sclub.jd.com', port=443): Max retries exceeded with url: /comment/productPageComments.action?productId=100002361195&score=0&sortType=6&page=0&pageSize=10&isShadowSku=0&rid=0&fold=1 (Caused by NewConnectionError('<urllib3.connection.VerifiedHTTPSConnection object at 0x00000191AAF3F358>: Failed to establish a new connection: [Errno 11001] getaddrinfo failed'))
2019-07-05 09:05:04,506 - root - ERROR - utils  - 161 - Amazon(https://www.amazon.co.uk/Zolo-Z2000-Liberty-Wireless-Headphones/dp/B075JBP2P7/ref=sr_1_2)报错信息：请求失败
Traceback (most recent call last):
  File "C:\Users\hhh\AppData\Local\Programs\Python\Python37\lib\site-packages\urllib3\connection.py", line 159, in _new_conn
    (self._dns_host, self.port), self.timeout, **extra_kw)
  File "C:\Users\hhh\AppData\Local\Programs\Python\Python37\lib\site-packages\urllib3\util\connection.py", line 57, in create_connection
    for res in socket.getaddrinfo(host, port, family, socket.SOCK_STREAM):
  File "C:\Users\hhh\AppData\Local\Programs\Python\Python37\lib\socket.py", line 748, in getaddrinfo
    for res in _socket.getaddrinfo(host, port, family, type, proto, flags):
socket.gaierror: [Errno 11001] getaddrinfo failed

During handling of the above exception, another exception occurred:

Traceback (most recent call last):
  File "C:\Users\hhh\AppData\Local\Programs\Python\Python37\lib\site-packages\urllib3\connectionpool.py", line 600, in urlopen
    chunked=chunked)
  File "C:\Users\hhh\AppData\Local\Programs\Python\Python37\lib\site-packages\urllib3\connectionpool.py", line 343, in _make_request
    self._validate_conn(conn)
  File "C:\Users\hhh\AppData\Local\Programs\Python\Python37\lib\site-packages\urllib3\connectionpool.py", line 839, in _validate_conn
    conn.connect()
  File "C:\Users\hhh\AppData\Local\Programs\Python\Python37\lib\site-packages\urllib3\connection.py", line 301, in connect
    conn = self._new_conn()
  File "C:\Users\hhh\AppData\Local\Programs\Python\Python37\lib\site-packages\urllib3\connection.py", line 168, in _new_conn
    self, "Failed to establish a new connection: %s" % e)
urllib3.exceptions.NewConnectionError: <urllib3.connection.VerifiedHTTPSConnection object at 0x00000191AAF496A0>: Failed to establish a new connection: [Errno 11001] getaddrinfo failed

During handling of the above exception, another exception occurred:

Traceback (most recent call last):
  File "C:\Users\hhh\AppData\Local\Programs\Python\Python37\lib\site-packages\requests\adapters.py", line 449, in send
    timeout=timeout
  File "C:\Users\hhh\AppData\Local\Programs\Python\Python37\lib\site-packages\urllib3\connectionpool.py", line 638, in urlopen
    _stacktrace=sys.exc_info()[2])
  File "C:\Users\hhh\AppData\Local\Programs\Python\Python37\lib\site-packages\urllib3\util\retry.py", line 398, in increment
    raise MaxRetryError(_pool, url, error or ResponseError(cause))
urllib3.exceptions.MaxRetryError: HTTPSConnectionPool(host='www.amazon.co.uk', port=443): Max retries exceeded with url: /Zolo-Z2000-Liberty-Wireless-Headphones/product-reviews/B075JBP2P7/ref=sr_1_2?filterByLanguage=en_US&sortBy=recent (Caused by NewConnectionError('<urllib3.connection.VerifiedHTTPSConnection object at 0x00000191AAF496A0>: Failed to establish a new connection: [Errno 11001] getaddrinfo failed'))

During handling of the above exception, another exception occurred:

Traceback (most recent call last):
  File "C:\Users\hhh\Desktop\Demo\reviews\amazon\amazon_review.py", line 228, in run
    review_html = self.parse_url(review_url)
  File "C:\Users\hhh\AppData\Local\Programs\Python\Python37\lib\site-packages\retrying.py", line 49, in wrapped_f
    return Retrying(*dargs, **dkw).call(f, *args, **kw)
  File "C:\Users\hhh\AppData\Local\Programs\Python\Python37\lib\site-packages\retrying.py", line 212, in call
    raise attempt.get()
  File "C:\Users\hhh\AppData\Local\Programs\Python\Python37\lib\site-packages\retrying.py", line 247, in get
    six.reraise(self.value[0], self.value[1], self.value[2])
  File "C:\Users\hhh\AppData\Local\Programs\Python\Python37\lib\site-packages\six.py", line 693, in reraise
    raise value
  File "C:\Users\hhh\AppData\Local\Programs\Python\Python37\lib\site-packages\retrying.py", line 200, in call
    attempt = Attempt(fn(*args, **kwargs), attempt_number, False)
  File "C:\Users\hhh\Desktop\Demo\reviews\amazon\amazon_review.py", line 38, in parse_url
    resp = requests.get(url, headers=self.headers, params=kw, timeout=100)
  File "C:\Users\hhh\AppData\Local\Programs\Python\Python37\lib\site-packages\requests\api.py", line 75, in get
    return request('get', url, params=params, **kwargs)
  File "C:\Users\hhh\AppData\Local\Programs\Python\Python37\lib\site-packages\requests\api.py", line 60, in request
    return session.request(method=method, url=url, **kwargs)
  File "C:\Users\hhh\AppData\Local\Programs\Python\Python37\lib\site-packages\requests\sessions.py", line 533, in request
    resp = self.send(prep, **send_kwargs)
  File "C:\Users\hhh\AppData\Local\Programs\Python\Python37\lib\site-packages\requests\sessions.py", line 646, in send
    r = adapter.send(request, **kwargs)
  File "C:\Users\hhh\AppData\Local\Programs\Python\Python37\lib\site-packages\requests\adapters.py", line 516, in send
    raise ConnectionError(e, request=request)
requests.exceptions.ConnectionError: HTTPSConnectionPool(host='www.amazon.co.uk', port=443): Max retries exceeded with url: /Zolo-Z2000-Liberty-Wireless-Headphones/product-reviews/B075JBP2P7/ref=sr_1_2?filterByLanguage=en_US&sortBy=recent (Caused by NewConnectionError('<urllib3.connection.VerifiedHTTPSConnection object at 0x00000191AAF496A0>: Failed to establish a new connection: [Errno 11001] getaddrinfo failed'))
2019-07-05 09:05:18,462 - root - ERROR - utils  - 161 - tmall(565187422922)报错信息：发送请求,进入评论页面失败
Traceback (most recent call last):
  File "C:\Users\hhh\Desktop\Demo\reviews\TMALL\tmall_review.py", line 205, in run
    self.enter_review()  # 发送请求,进入评论页面
  File "C:\Users\hhh\Desktop\Demo\reviews\TMALL\tmall_review.py", line 59, in enter_review
    self.click_review()
  File "C:\Users\hhh\Desktop\Demo\reviews\TMALL\tmall_review.py", line 88, in click_review
    EC.element_to_be_clickable((By.XPATH, "//div[@id='J_TabBarBox']//a[text()='累计评价 ']"))).click()
  File "C:\Users\hhh\AppData\Local\Programs\Python\Python37\lib\site-packages\selenium\webdriver\support\wait.py", line 80, in until
    raise TimeoutException(message, screen, stacktrace)
selenium.common.exceptions.TimeoutException: Message: 

2019-07-05 09:05:40,758 - root - ERROR - utils  - 161 - Amazon(https://www.amazon.co.jp/Liberty-Bluetooth-%E5%AE%8C%E5%85%A8%E3%83%AF%E3%82%A4%E3%83%A4%E3%83%AC%E3%82%B9%E3%82%A4%E3%83%A4%E3%83%9B%E3%83%B3-%E3%80%90%E6%9C%80%E5%A4%A724%E6%99%82%E9%96%93%E9%9F%B3%E6%A5%BD%E5%86%8D%E7%94%9F-IPX5%E9%98%B2%E6%B0%B4%E8%A6%8F%E6%A0%BC%E3%80%91/dp/B075SSLKDB/ref=sr_1_1)报错信息：请求失败
Traceback (most recent call last):
  File "C:\Users\hhh\AppData\Local\Programs\Python\Python37\lib\site-packages\urllib3\contrib\pyopenssl.py", line 453, in wrap_socket
    cnx.do_handshake()
  File "C:\Users\hhh\AppData\Local\Programs\Python\Python37\lib\site-packages\OpenSSL\SSL.py", line 1915, in do_handshake
    self._raise_ssl_error(self._ssl, result)
  File "C:\Users\hhh\AppData\Local\Programs\Python\Python37\lib\site-packages\OpenSSL\SSL.py", line 1639, in _raise_ssl_error
    raise SysCallError(errno, errorcode.get(errno))
OpenSSL.SSL.SysCallError: (10054, 'WSAECONNRESET')

During handling of the above exception, another exception occurred:

Traceback (most recent call last):
  File "C:\Users\hhh\AppData\Local\Programs\Python\Python37\lib\site-packages\urllib3\connectionpool.py", line 600, in urlopen
    chunked=chunked)
  File "C:\Users\hhh\AppData\Local\Programs\Python\Python37\lib\site-packages\urllib3\connectionpool.py", line 343, in _make_request
    self._validate_conn(conn)
  File "C:\Users\hhh\AppData\Local\Programs\Python\Python37\lib\site-packages\urllib3\connectionpool.py", line 839, in _validate_conn
    conn.connect()
  File "C:\Users\hhh\AppData\Local\Programs\Python\Python37\lib\site-packages\urllib3\connection.py", line 344, in connect
    ssl_context=context)
  File "C:\Users\hhh\AppData\Local\Programs\Python\Python37\lib\site-packages\urllib3\util\ssl_.py", line 344, in ssl_wrap_socket
    return context.wrap_socket(sock, server_hostname=server_hostname)
  File "C:\Users\hhh\AppData\Local\Programs\Python\Python37\lib\site-packages\urllib3\contrib\pyopenssl.py", line 459, in wrap_socket
    raise ssl.SSLError('bad handshake: %r' % e)
ssl.SSLError: ("bad handshake: SysCallError(10054, 'WSAECONNRESET')",)

During handling of the above exception, another exception occurred:

Traceback (most recent call last):
  File "C:\Users\hhh\AppData\Local\Programs\Python\Python37\lib\site-packages\requests\adapters.py", line 449, in send
    timeout=timeout
  File "C:\Users\hhh\AppData\Local\Programs\Python\Python37\lib\site-packages\urllib3\connectionpool.py", line 638, in urlopen
    _stacktrace=sys.exc_info()[2])
  File "C:\Users\hhh\AppData\Local\Programs\Python\Python37\lib\site-packages\urllib3\util\retry.py", line 398, in increment
    raise MaxRetryError(_pool, url, error or ResponseError(cause))
urllib3.exceptions.MaxRetryError: HTTPSConnectionPool(host='www.amazon.co.jp', port=443): Max retries exceeded with url: /Liberty-Bluetooth-%E5%AE%8C%E5%85%A8%E3%83%AF%E3%82%A4%E3%83%A4%E3%83%AC%E3%82%B9%E3%82%A4%E3%83%A4%E3%83%9B%E3%83%B3-%E3%80%90%E6%9C%80%E5%A4%A724%E6%99%82%E9%96%93%E9%9F%B3%E6%A5%BD%E5%86%8D%E7%94%9F-IPX5%E9%98%B2%E6%B0%B4%E8%A6%8F%E6%A0%BC%E3%80%91/product-reviews/B075SSLKDB/ref=sr_1_1?sortBy=recent&language=zh_CN (Caused by SSLError(SSLError("bad handshake: SysCallError(10054, 'WSAECONNRESET')")))

During handling of the above exception, another exception occurred:

Traceback (most recent call last):
  File "C:\Users\hhh\Desktop\Demo\reviews\amazon\amazon_review.py", line 228, in run
    review_html = self.parse_url(review_url)
  File "C:\Users\hhh\AppData\Local\Programs\Python\Python37\lib\site-packages\retrying.py", line 49, in wrapped_f
    return Retrying(*dargs, **dkw).call(f, *args, **kw)
  File "C:\Users\hhh\AppData\Local\Programs\Python\Python37\lib\site-packages\retrying.py", line 212, in call
    raise attempt.get()
  File "C:\Users\hhh\AppData\Local\Programs\Python\Python37\lib\site-packages\retrying.py", line 247, in get
    six.reraise(self.value[0], self.value[1], self.value[2])
  File "C:\Users\hhh\AppData\Local\Programs\Python\Python37\lib\site-packages\six.py", line 693, in reraise
    raise value
  File "C:\Users\hhh\AppData\Local\Programs\Python\Python37\lib\site-packages\retrying.py", line 200, in call
    attempt = Attempt(fn(*args, **kwargs), attempt_number, False)
  File "C:\Users\hhh\Desktop\Demo\reviews\amazon\amazon_review.py", line 38, in parse_url
    resp = requests.get(url, headers=self.headers, params=kw, timeout=100)
  File "C:\Users\hhh\AppData\Local\Programs\Python\Python37\lib\site-packages\requests\api.py", line 75, in get
    return request('get', url, params=params, **kwargs)
  File "C:\Users\hhh\AppData\Local\Programs\Python\Python37\lib\site-packages\requests\api.py", line 60, in request
    return session.request(method=method, url=url, **kwargs)
  File "C:\Users\hhh\AppData\Local\Programs\Python\Python37\lib\site-packages\requests\sessions.py", line 533, in request
    resp = self.send(prep, **send_kwargs)
  File "C:\Users\hhh\AppData\Local\Programs\Python\Python37\lib\site-packages\requests\sessions.py", line 646, in send
    r = adapter.send(request, **kwargs)
  File "C:\Users\hhh\AppData\Local\Programs\Python\Python37\lib\site-packages\requests\adapters.py", line 514, in send
    raise SSLError(e, request=request)
requests.exceptions.SSLError: HTTPSConnectionPool(host='www.amazon.co.jp', port=443): Max retries exceeded with url: /Liberty-Bluetooth-%E5%AE%8C%E5%85%A8%E3%83%AF%E3%82%A4%E3%83%A4%E3%83%AC%E3%82%B9%E3%82%A4%E3%83%A4%E3%83%9B%E3%83%B3-%E3%80%90%E6%9C%80%E5%A4%A724%E6%99%82%E9%96%93%E9%9F%B3%E6%A5%BD%E5%86%8D%E7%94%9F-IPX5%E9%98%B2%E6%B0%B4%E8%A6%8F%E6%A0%BC%E3%80%91/product-reviews/B075SSLKDB/ref=sr_1_1?sortBy=recent&language=zh_CN (Caused by SSLError(SSLError("bad handshake: SysCallError(10054, 'WSAECONNRESET')")))
2019-07-05 09:06:40,492 - root - ERROR - utils  - 161 - tmall(552634156539)报错信息：发送请求,进入评论页面失败
Traceback (most recent call last):
  File "C:\Users\hhh\Desktop\Demo\reviews\TMALL\tmall_review.py", line 205, in run
    self.enter_review()  # 发送请求,进入评论页面
  File "C:\Users\hhh\Desktop\Demo\reviews\TMALL\tmall_review.py", line 63, in enter_review
    self.order_time()
  File "C:\Users\hhh\Desktop\Demo\reviews\TMALL\tmall_review.py", line 102, in order_time
    element_artist[1].click()
  File "C:\Users\hhh\AppData\Local\Programs\Python\Python37\lib\site-packages\selenium\webdriver\remote\webelement.py", line 80, in click
    self._execute(Command.CLICK_ELEMENT)
  File "C:\Users\hhh\AppData\Local\Programs\Python\Python37\lib\site-packages\selenium\webdriver\remote\webelement.py", line 633, in _execute
    return self._parent.execute(command, params)
  File "C:\Users\hhh\AppData\Local\Programs\Python\Python37\lib\site-packages\selenium\webdriver\remote\webdriver.py", line 321, in execute
    self.error_handler.check_response(response)
  File "C:\Users\hhh\AppData\Local\Programs\Python\Python37\lib\site-packages\selenium\webdriver\remote\errorhandler.py", line 242, in check_response
    raise exception_class(message, screen, stacktrace)
selenium.common.exceptions.ElementNotVisibleException: Message: element not interactable
  (Session info: chrome=75.0.3770.100)
  (Driver info: chromedriver=74.0.3729.6 (255758eccf3d244491b8a1317aa76e1ce10d57e9-refs/branch-heads/3729@{#29}),platform=Windows NT 10.0.17763 x86_64)

2019-07-05 09:08:05,679 - root - ERROR - utils  - 161 - tmall(580233296207)报错信息：发送请求,进入评论页面失败
Traceback (most recent call last):
  File "C:\Users\hhh\Desktop\Demo\reviews\TMALL\tmall_review.py", line 205, in run
    self.enter_review()  # 发送请求,进入评论页面
  File "C:\Users\hhh\Desktop\Demo\reviews\TMALL\tmall_review.py", line 59, in enter_review
    self.click_review()
  File "C:\Users\hhh\Desktop\Demo\reviews\TMALL\tmall_review.py", line 88, in click_review
    EC.element_to_be_clickable((By.XPATH, "//div[@id='J_TabBarBox']//a[text()='累计评价 ']"))).click()
  File "C:\Users\hhh\AppData\Local\Programs\Python\Python37\lib\site-packages\selenium\webdriver\support\wait.py", line 80, in until
    raise TimeoutException(message, screen, stacktrace)
selenium.common.exceptions.TimeoutException: Message: 

2019-07-05 09:08:44,342 - root - ERROR - utils  - 161 - tmall(574870586003)报错信息：发送请求,进入评论页面失败
Traceback (most recent call last):
  File "C:\Users\hhh\Desktop\Demo\reviews\TMALL\tmall_review.py", line 205, in run
    self.enter_review()  # 发送请求,进入评论页面
  File "C:\Users\hhh\Desktop\Demo\reviews\TMALL\tmall_review.py", line 53, in enter_review
    self.parse_url()
  File "C:\Users\hhh\AppData\Local\Programs\Python\Python37\lib\site-packages\retrying.py", line 49, in wrapped_f
    return Retrying(*dargs, **dkw).call(f, *args, **kw)
  File "C:\Users\hhh\AppData\Local\Programs\Python\Python37\lib\site-packages\retrying.py", line 212, in call
    raise attempt.get()
  File "C:\Users\hhh\AppData\Local\Programs\Python\Python37\lib\site-packages\retrying.py", line 247, in get
    six.reraise(self.value[0], self.value[1], self.value[2])
  File "C:\Users\hhh\AppData\Local\Programs\Python\Python37\lib\site-packages\six.py", line 693, in reraise
    raise value
  File "C:\Users\hhh\AppData\Local\Programs\Python\Python37\lib\site-packages\retrying.py", line 200, in call
    attempt = Attempt(fn(*args, **kwargs), attempt_number, False)
  File "C:\Users\hhh\Desktop\Demo\reviews\TMALL\tmall_review.py", line 45, in parse_url
    self.driver.maximize_window()
  File "C:\Users\hhh\AppData\Local\Programs\Python\Python37\lib\site-packages\selenium\webdriver\remote\webdriver.py", line 737, in maximize_window
    self.execute(command, params)
  File "C:\Users\hhh\AppData\Local\Programs\Python\Python37\lib\site-packages\selenium\webdriver\remote\webdriver.py", line 321, in execute
    self.error_handler.check_response(response)
  File "C:\Users\hhh\AppData\Local\Programs\Python\Python37\lib\site-packages\selenium\webdriver\remote\errorhandler.py", line 242, in check_response
    raise exception_class(message, screen, stacktrace)
selenium.common.exceptions.WebDriverException: Message: chrome not reachable
  (Session info: chrome=75.0.3770.100)
  (Driver info: chromedriver=74.0.3729.6 (255758eccf3d244491b8a1317aa76e1ce10d57e9-refs/branch-heads/3729@{#29}),platform=Windows NT 10.0.17763 x86_64)

2019-07-05 09:10:14,733 - root - ERROR - utils  - 161 - Amazon(https://www.amazon.co.jp/%E3%82%BD%E3%83%95%E3%83%88%E3%83%90%E3%83%B3%E3%82%AF%E3%82%BB%E3%83%AC%E3%82%AF%E3%82%B7%E3%83%A7%E3%83%B3-Bluetooth%E3%82%A4%E3%83%A4%E3%83%9B%E3%83%B3%EF%BC%88%E3%83%96%E3%83%A9%E3%83%83%E3%82%AF%EF%BC%89SoftBank-GLIDiC-SB-WS72-MRTW-BK/dp/B07KNK8XCP/ref=sr_1_1)报错信息：请求失败
Traceback (most recent call last):
  File "C:\Users\hhh\AppData\Local\Programs\Python\Python37\lib\site-packages\urllib3\contrib\pyopenssl.py", line 453, in wrap_socket
    cnx.do_handshake()
  File "C:\Users\hhh\AppData\Local\Programs\Python\Python37\lib\site-packages\OpenSSL\SSL.py", line 1915, in do_handshake
    self._raise_ssl_error(self._ssl, result)
  File "C:\Users\hhh\AppData\Local\Programs\Python\Python37\lib\site-packages\OpenSSL\SSL.py", line 1639, in _raise_ssl_error
    raise SysCallError(errno, errorcode.get(errno))
OpenSSL.SSL.SysCallError: (10054, 'WSAECONNRESET')

During handling of the above exception, another exception occurred:

Traceback (most recent call last):
  File "C:\Users\hhh\AppData\Local\Programs\Python\Python37\lib\site-packages\urllib3\connectionpool.py", line 600, in urlopen
    chunked=chunked)
  File "C:\Users\hhh\AppData\Local\Programs\Python\Python37\lib\site-packages\urllib3\connectionpool.py", line 343, in _make_request
    self._validate_conn(conn)
  File "C:\Users\hhh\AppData\Local\Programs\Python\Python37\lib\site-packages\urllib3\connectionpool.py", line 839, in _validate_conn
    conn.connect()
  File "C:\Users\hhh\AppData\Local\Programs\Python\Python37\lib\site-packages\urllib3\connection.py", line 344, in connect
    ssl_context=context)
  File "C:\Users\hhh\AppData\Local\Programs\Python\Python37\lib\site-packages\urllib3\util\ssl_.py", line 344, in ssl_wrap_socket
    return context.wrap_socket(sock, server_hostname=server_hostname)
  File "C:\Users\hhh\AppData\Local\Programs\Python\Python37\lib\site-packages\urllib3\contrib\pyopenssl.py", line 459, in wrap_socket
    raise ssl.SSLError('bad handshake: %r' % e)
ssl.SSLError: ("bad handshake: SysCallError(10054, 'WSAECONNRESET')",)

During handling of the above exception, another exception occurred:

Traceback (most recent call last):
  File "C:\Users\hhh\AppData\Local\Programs\Python\Python37\lib\site-packages\requests\adapters.py", line 449, in send
    timeout=timeout
  File "C:\Users\hhh\AppData\Local\Programs\Python\Python37\lib\site-packages\urllib3\connectionpool.py", line 638, in urlopen
    _stacktrace=sys.exc_info()[2])
  File "C:\Users\hhh\AppData\Local\Programs\Python\Python37\lib\site-packages\urllib3\util\retry.py", line 398, in increment
    raise MaxRetryError(_pool, url, error or ResponseError(cause))
urllib3.exceptions.MaxRetryError: HTTPSConnectionPool(host='www.amazon.co.jp', port=443): Max retries exceeded with url: /%E3%82%BD%E3%83%95%E3%83%88%E3%83%90%E3%83%B3%E3%82%AF%E3%82%BB%E3%83%AC%E3%82%AF%E3%82%B7%E3%83%A7%E3%83%B3-Bluetooth%E3%82%A4%E3%83%A4%E3%83%9B%E3%83%B3%EF%BC%88%E3%83%96%E3%83%A9%E3%83%83%E3%82%AF%EF%BC%89SoftBank-GLIDiC-SB-WS72-MRTW-BK/product-reviews/B07KNK8XCP/ref=sr_1_1?sortBy=recent&language=zh_CN (Caused by SSLError(SSLError("bad handshake: SysCallError(10054, 'WSAECONNRESET')")))

During handling of the above exception, another exception occurred:

Traceback (most recent call last):
  File "C:\Users\hhh\Desktop\Demo\reviews\amazon\amazon_review.py", line 228, in run
    review_html = self.parse_url(review_url)
  File "C:\Users\hhh\AppData\Local\Programs\Python\Python37\lib\site-packages\retrying.py", line 49, in wrapped_f
    return Retrying(*dargs, **dkw).call(f, *args, **kw)
  File "C:\Users\hhh\AppData\Local\Programs\Python\Python37\lib\site-packages\retrying.py", line 212, in call
    raise attempt.get()
  File "C:\Users\hhh\AppData\Local\Programs\Python\Python37\lib\site-packages\retrying.py", line 247, in get
    six.reraise(self.value[0], self.value[1], self.value[2])
  File "C:\Users\hhh\AppData\Local\Programs\Python\Python37\lib\site-packages\six.py", line 693, in reraise
    raise value
  File "C:\Users\hhh\AppData\Local\Programs\Python\Python37\lib\site-packages\retrying.py", line 200, in call
    attempt = Attempt(fn(*args, **kwargs), attempt_number, False)
  File "C:\Users\hhh\Desktop\Demo\reviews\amazon\amazon_review.py", line 38, in parse_url
    resp = requests.get(url, headers=self.headers, params=kw, timeout=100)
  File "C:\Users\hhh\AppData\Local\Programs\Python\Python37\lib\site-packages\requests\api.py", line 75, in get
    return request('get', url, params=params, **kwargs)
  File "C:\Users\hhh\AppData\Local\Programs\Python\Python37\lib\site-packages\requests\api.py", line 60, in request
    return session.request(method=method, url=url, **kwargs)
  File "C:\Users\hhh\AppData\Local\Programs\Python\Python37\lib\site-packages\requests\sessions.py", line 533, in request
    resp = self.send(prep, **send_kwargs)
  File "C:\Users\hhh\AppData\Local\Programs\Python\Python37\lib\site-packages\requests\sessions.py", line 646, in send
    r = adapter.send(request, **kwargs)
  File "C:\Users\hhh\AppData\Local\Programs\Python\Python37\lib\site-packages\requests\adapters.py", line 514, in send
    raise SSLError(e, request=request)
requests.exceptions.SSLError: HTTPSConnectionPool(host='www.amazon.co.jp', port=443): Max retries exceeded with url: /%E3%82%BD%E3%83%95%E3%83%88%E3%83%90%E3%83%B3%E3%82%AF%E3%82%BB%E3%83%AC%E3%82%AF%E3%82%B7%E3%83%A7%E3%83%B3-Bluetooth%E3%82%A4%E3%83%A4%E3%83%9B%E3%83%B3%EF%BC%88%E3%83%96%E3%83%A9%E3%83%83%E3%82%AF%EF%BC%89SoftBank-GLIDiC-SB-WS72-MRTW-BK/product-reviews/B07KNK8XCP/ref=sr_1_1?sortBy=recent&language=zh_CN (Caused by SSLError(SSLError("bad handshake: SysCallError(10054, 'WSAECONNRESET')")))
