2019-07-05 08:45:33,615 - root - ERROR - utils  - 161 - JD(41014808466)报错信息：数据库保存/更新失败
Traceback (most recent call last):
  File "C:\Users\hhh\Desktop\Demo\reviews\JD\jd_review.py", line 157, in save_data
    c.execute(sql)
cx_Oracle.IntegrityError: ORA-00001: 违反唯一约束条件 (EIP.ECOMMERCE_REVIEW_PIX3)
2019-07-05 08:45:33,625 - root - ERROR - utils  - 161 - JD(41014808466)报错信息：数据库保存/更新失败
Traceback (most recent call last):
  File "C:\Users\hhh\Desktop\Demo\reviews\JD\jd_review.py", line 157, in save_data
    c.execute(sql)
cx_Oracle.IntegrityError: ORA-00001: 违反唯一约束条件 (EIP.ECOMMERCE_REVIEW_PIX3)
2019-07-05 08:45:33,632 - root - ERROR - utils  - 161 - JD(41014808466)报错信息：数据库保存/更新失败
Traceback (most recent call last):
  File "C:\Users\hhh\Desktop\Demo\reviews\JD\jd_review.py", line 157, in save_data
    c.execute(sql)
cx_Oracle.IntegrityError: ORA-00001: 违反唯一约束条件 (EIP.ECOMMERCE_REVIEW_PIX3)
2019-07-05 08:45:41,226 - root - ERROR - utils  - 161 - JD(100001470134)报错信息：数据库保存/更新失败
Traceback (most recent call last):
  File "C:\Users\hhh\Desktop\Demo\reviews\JD\jd_review.py", line 157, in save_data
    c.execute(sql)
cx_Oracle.IntegrityError: ORA-00001: 违反唯一约束条件 (EIP.ECOMMERCE_REVIEW_PIX3)
2019-07-05 08:45:41,237 - root - ERROR - utils  - 161 - JD(100001470134)报错信息：数据库保存/更新失败
Traceback (most recent call last):
  File "C:\Users\hhh\Desktop\Demo\reviews\JD\jd_review.py", line 157, in save_data
    c.execute(sql)
cx_Oracle.IntegrityError: ORA-00001: 违反唯一约束条件 (EIP.ECOMMERCE_REVIEW_PIX3)
2019-07-05 08:45:41,248 - root - ERROR - utils  - 161 - JD(100001470134)报错信息：数据库保存/更新失败
Traceback (most recent call last):
  File "C:\Users\hhh\Desktop\Demo\reviews\JD\jd_review.py", line 157, in save_data
    c.execute(sql)
cx_Oracle.IntegrityError: ORA-00001: 违反唯一约束条件 (EIP.ECOMMERCE_REVIEW_PIX3)
2019-07-05 08:45:41,254 - root - ERROR - utils  - 161 - JD(100001470134)报错信息：数据库保存/更新失败
Traceback (most recent call last):
  File "C:\Users\hhh\Desktop\Demo\reviews\JD\jd_review.py", line 157, in save_data
    c.execute(sql)
cx_Oracle.IntegrityError: ORA-00001: 违反唯一约束条件 (EIP.ECOMMERCE_REVIEW_PIX3)
2019-07-05 08:45:41,259 - root - ERROR - utils  - 161 - JD(100001470134)报错信息：数据库保存/更新失败
Traceback (most recent call last):
  File "C:\Users\hhh\Desktop\Demo\reviews\JD\jd_review.py", line 157, in save_data
    c.execute(sql)
cx_Oracle.IntegrityError: ORA-00001: 违反唯一约束条件 (EIP.ECOMMERCE_REVIEW_PIX3)
2019-07-05 08:45:41,265 - root - ERROR - utils  - 161 - JD(100001470134)报错信息：数据库保存/更新失败
Traceback (most recent call last):
  File "C:\Users\hhh\Desktop\Demo\reviews\JD\jd_review.py", line 157, in save_data
    c.execute(sql)
cx_Oracle.IntegrityError: ORA-00001: 违反唯一约束条件 (EIP.ECOMMERCE_REVIEW_PIX3)
2019-07-05 08:45:41,271 - root - ERROR - utils  - 161 - JD(100001470134)报错信息：数据库保存/更新失败
Traceback (most recent call last):
  File "C:\Users\hhh\Desktop\Demo\reviews\JD\jd_review.py", line 157, in save_data
    c.execute(sql)
cx_Oracle.IntegrityError: ORA-00001: 违反唯一约束条件 (EIP.ECOMMERCE_REVIEW_PIX3)
2019-07-05 08:45:41,277 - root - ERROR - utils  - 161 - JD(100001470134)报错信息：数据库保存/更新失败
Traceback (most recent call last):
  File "C:\Users\hhh\Desktop\Demo\reviews\JD\jd_review.py", line 157, in save_data
    c.execute(sql)
cx_Oracle.IntegrityError: ORA-00001: 违反唯一约束条件 (EIP.ECOMMERCE_REVIEW_PIX3)
2019-07-05 08:45:41,282 - root - ERROR - utils  - 161 - JD(100001470134)报错信息：数据库保存/更新失败
Traceback (most recent call last):
  File "C:\Users\hhh\Desktop\Demo\reviews\JD\jd_review.py", line 157, in save_data
    c.execute(sql)
cx_Oracle.IntegrityError: ORA-00001: 违反唯一约束条件 (EIP.ECOMMERCE_REVIEW_PIX3)
2019-07-05 08:45:41,288 - root - ERROR - utils  - 161 - JD(100001470134)报错信息：数据库保存/更新失败
Traceback (most recent call last):
  File "C:\Users\hhh\Desktop\Demo\reviews\JD\jd_review.py", line 157, in save_data
    c.execute(sql)
cx_Oracle.IntegrityError: ORA-00001: 违反唯一约束条件 (EIP.ECOMMERCE_REVIEW_PIX3)
2019-07-05 08:45:41,294 - root - ERROR - utils  - 161 - JD(100001470134)报错信息：数据库保存/更新失败
Traceback (most recent call last):
  File "C:\Users\hhh\Desktop\Demo\reviews\JD\jd_review.py", line 157, in save_data
    c.execute(sql)
cx_Oracle.IntegrityError: ORA-00001: 违反唯一约束条件 (EIP.ECOMMERCE_REVIEW_PIX3)
2019-07-05 08:45:41,299 - root - ERROR - utils  - 161 - JD(100001470134)报错信息：数据库保存/更新失败
Traceback (most recent call last):
  File "C:\Users\hhh\Desktop\Demo\reviews\JD\jd_review.py", line 157, in save_data
    c.execute(sql)
cx_Oracle.IntegrityError: ORA-00001: 违反唯一约束条件 (EIP.ECOMMERCE_REVIEW_PIX3)
2019-07-05 08:45:41,311 - root - ERROR - utils  - 161 - JD(100001470134)报错信息：数据库保存/更新失败
Traceback (most recent call last):
  File "C:\Users\hhh\Desktop\Demo\reviews\JD\jd_review.py", line 157, in save_data
    c.execute(sql)
cx_Oracle.IntegrityError: ORA-00001: 违反唯一约束条件 (EIP.ECOMMERCE_REVIEW_PIX3)
2019-07-05 08:45:41,317 - root - ERROR - utils  - 161 - JD(100001470134)报错信息：数据库保存/更新失败
Traceback (most recent call last):
  File "C:\Users\hhh\Desktop\Demo\reviews\JD\jd_review.py", line 157, in save_data
    c.execute(sql)
cx_Oracle.IntegrityError: ORA-00001: 违反唯一约束条件 (EIP.ECOMMERCE_REVIEW_PIX3)
2019-07-05 08:45:41,323 - root - ERROR - utils  - 161 - JD(100001470134)报错信息：数据库保存/更新失败
Traceback (most recent call last):
  File "C:\Users\hhh\Desktop\Demo\reviews\JD\jd_review.py", line 157, in save_data
    c.execute(sql)
cx_Oracle.IntegrityError: ORA-00001: 违反唯一约束条件 (EIP.ECOMMERCE_REVIEW_PIX3)
2019-07-05 08:45:41,328 - root - ERROR - utils  - 161 - JD(100001470134)报错信息：数据库保存/更新失败
Traceback (most recent call last):
  File "C:\Users\hhh\Desktop\Demo\reviews\JD\jd_review.py", line 157, in save_data
    c.execute(sql)
cx_Oracle.IntegrityError: ORA-00001: 违反唯一约束条件 (EIP.ECOMMERCE_REVIEW_PIX3)
2019-07-05 08:45:42,029 - root - ERROR - utils  - 161 - JD(2245024)报错信息：数据库保存/更新失败
Traceback (most recent call last):
  File "C:\Users\hhh\Desktop\Demo\reviews\JD\jd_review.py", line 157, in save_data
    c.execute(sql)
cx_Oracle.IntegrityError: ORA-00001: 违反唯一约束条件 (EIP.ECOMMERCE_REVIEW_PIX3)
2019-07-05 08:45:42,037 - root - ERROR - utils  - 161 - JD(2245024)报错信息：数据库保存/更新失败
Traceback (most recent call last):
  File "C:\Users\hhh\Desktop\Demo\reviews\JD\jd_review.py", line 157, in save_data
    c.execute(sql)
cx_Oracle.IntegrityError: ORA-00001: 违反唯一约束条件 (EIP.ECOMMERCE_REVIEW_PIX3)
2019-07-05 08:45:42,043 - root - ERROR - utils  - 161 - JD(2245024)报错信息：数据库保存/更新失败
Traceback (most recent call last):
  File "C:\Users\hhh\Desktop\Demo\reviews\JD\jd_review.py", line 157, in save_data
    c.execute(sql)
cx_Oracle.IntegrityError: ORA-00001: 违反唯一约束条件 (EIP.ECOMMERCE_REVIEW_PIX3)
2019-07-05 08:45:42,048 - root - ERROR - utils  - 161 - JD(2245024)报错信息：数据库保存/更新失败
Traceback (most recent call last):
  File "C:\Users\hhh\Desktop\Demo\reviews\JD\jd_review.py", line 157, in save_data
    c.execute(sql)
cx_Oracle.IntegrityError: ORA-00001: 违反唯一约束条件 (EIP.ECOMMERCE_REVIEW_PIX3)
2019-07-05 08:45:42,054 - root - ERROR - utils  - 161 - JD(2245024)报错信息：数据库保存/更新失败
Traceback (most recent call last):
  File "C:\Users\hhh\Desktop\Demo\reviews\JD\jd_review.py", line 157, in save_data
    c.execute(sql)
cx_Oracle.IntegrityError: ORA-00001: 违反唯一约束条件 (EIP.ECOMMERCE_REVIEW_PIX3)
2019-07-05 08:45:42,066 - root - ERROR - utils  - 161 - JD(2245024)报错信息：数据库保存/更新失败
Traceback (most recent call last):
  File "C:\Users\hhh\Desktop\Demo\reviews\JD\jd_review.py", line 157, in save_data
    c.execute(sql)
cx_Oracle.IntegrityError: ORA-00001: 违反唯一约束条件 (EIP.ECOMMERCE_REVIEW_PIX3)
2019-07-05 08:45:49,420 - root - ERROR - utils  - 161 - Amazon(https://www.amazon.co.jp/Zero-Audio-TWZ-1000-%E5%AE%8C%E5%85%A8%E3%83%AF%E3%82%A4%E3%83%A4%E3%83%AC%E3%82%B9%E3%82%B9%E3%83%86%E3%83%AC%E3%82%AA%E3%83%98%E3%83%83%E3%83%89%E3%83%9B%E3%83%B3/dp/B07N6NRS8Q/ref=sr_1_1)报错信息：请求失败
Traceback (most recent call last):
  File "C:\Users\hhh\AppData\Local\Programs\Python\Python37\lib\site-packages\urllib3\contrib\pyopenssl.py", line 453, in wrap_socket
    cnx.do_handshake()
  File "C:\Users\hhh\AppData\Local\Programs\Python\Python37\lib\site-packages\OpenSSL\SSL.py", line 1915, in do_handshake
    self._raise_ssl_error(self._ssl, result)
  File "C:\Users\hhh\AppData\Local\Programs\Python\Python37\lib\site-packages\OpenSSL\SSL.py", line 1639, in _raise_ssl_error
    raise SysCallError(errno, errorcode.get(errno))
OpenSSL.SSL.SysCallError: (10054, 'WSAECONNRESET')

During handling of the above exception, another exception occurred:

Traceback (most recent call last):
  File "C:\Users\hhh\AppData\Local\Programs\Python\Python37\lib\site-packages\urllib3\connectionpool.py", line 600, in urlopen
    chunked=chunked)
  File "C:\Users\hhh\AppData\Local\Programs\Python\Python37\lib\site-packages\urllib3\connectionpool.py", line 343, in _make_request
    self._validate_conn(conn)
  File "C:\Users\hhh\AppData\Local\Programs\Python\Python37\lib\site-packages\urllib3\connectionpool.py", line 839, in _validate_conn
    conn.connect()
  File "C:\Users\hhh\AppData\Local\Programs\Python\Python37\lib\site-packages\urllib3\connection.py", line 344, in connect
    ssl_context=context)
  File "C:\Users\hhh\AppData\Local\Programs\Python\Python37\lib\site-packages\urllib3\util\ssl_.py", line 344, in ssl_wrap_socket
    return context.wrap_socket(sock, server_hostname=server_hostname)
  File "C:\Users\hhh\AppData\Local\Programs\Python\Python37\lib\site-packages\urllib3\contrib\pyopenssl.py", line 459, in wrap_socket
    raise ssl.SSLError('bad handshake: %r' % e)
ssl.SSLError: ("bad handshake: SysCallError(10054, 'WSAECONNRESET')",)

During handling of the above exception, another exception occurred:

Traceback (most recent call last):
  File "C:\Users\hhh\AppData\Local\Programs\Python\Python37\lib\site-packages\requests\adapters.py", line 449, in send
    timeout=timeout
  File "C:\Users\hhh\AppData\Local\Programs\Python\Python37\lib\site-packages\urllib3\connectionpool.py", line 638, in urlopen
    _stacktrace=sys.exc_info()[2])
  File "C:\Users\hhh\AppData\Local\Programs\Python\Python37\lib\site-packages\urllib3\util\retry.py", line 398, in increment
    raise MaxRetryError(_pool, url, error or ResponseError(cause))
urllib3.exceptions.MaxRetryError: HTTPSConnectionPool(host='www.amazon.co.jp', port=443): Max retries exceeded with url: /Zero-Audio-TWZ-1000-%E5%AE%8C%E5%85%A8%E3%83%AF%E3%82%A4%E3%83%A4%E3%83%AC%E3%82%B9%E3%82%B9%E3%83%86%E3%83%AC%E3%82%AA%E3%83%98%E3%83%83%E3%83%89%E3%83%9B%E3%83%B3/product-reviews/B07N6NRS8Q/ref=sr_1_1?sortBy=recent&language=zh_CN (Caused by SSLError(SSLError("bad handshake: SysCallError(10054, 'WSAECONNRESET')")))

During handling of the above exception, another exception occurred:

Traceback (most recent call last):
  File "C:\Users\hhh\Desktop\Demo\reviews\amazon\amazon_review.py", line 228, in run
    review_html = self.parse_url(review_url)
  File "C:\Users\hhh\AppData\Local\Programs\Python\Python37\lib\site-packages\retrying.py", line 49, in wrapped_f
    return Retrying(*dargs, **dkw).call(f, *args, **kw)
  File "C:\Users\hhh\AppData\Local\Programs\Python\Python37\lib\site-packages\retrying.py", line 212, in call
    raise attempt.get()
  File "C:\Users\hhh\AppData\Local\Programs\Python\Python37\lib\site-packages\retrying.py", line 247, in get
    six.reraise(self.value[0], self.value[1], self.value[2])
  File "C:\Users\hhh\AppData\Local\Programs\Python\Python37\lib\site-packages\six.py", line 693, in reraise
    raise value
  File "C:\Users\hhh\AppData\Local\Programs\Python\Python37\lib\site-packages\retrying.py", line 200, in call
    attempt = Attempt(fn(*args, **kwargs), attempt_number, False)
  File "C:\Users\hhh\Desktop\Demo\reviews\amazon\amazon_review.py", line 38, in parse_url
    resp = requests.get(url, headers=self.headers, params=kw, timeout=100)
  File "C:\Users\hhh\AppData\Local\Programs\Python\Python37\lib\site-packages\requests\api.py", line 75, in get
    return request('get', url, params=params, **kwargs)
  File "C:\Users\hhh\AppData\Local\Programs\Python\Python37\lib\site-packages\requests\api.py", line 60, in request
    return session.request(method=method, url=url, **kwargs)
  File "C:\Users\hhh\AppData\Local\Programs\Python\Python37\lib\site-packages\requests\sessions.py", line 533, in request
    resp = self.send(prep, **send_kwargs)
  File "C:\Users\hhh\AppData\Local\Programs\Python\Python37\lib\site-packages\requests\sessions.py", line 646, in send
    r = adapter.send(request, **kwargs)
  File "C:\Users\hhh\AppData\Local\Programs\Python\Python37\lib\site-packages\requests\adapters.py", line 514, in send
    raise SSLError(e, request=request)
requests.exceptions.SSLError: HTTPSConnectionPool(host='www.amazon.co.jp', port=443): Max retries exceeded with url: /Zero-Audio-TWZ-1000-%E5%AE%8C%E5%85%A8%E3%83%AF%E3%82%A4%E3%83%A4%E3%83%AC%E3%82%B9%E3%82%B9%E3%83%86%E3%83%AC%E3%82%AA%E3%83%98%E3%83%83%E3%83%89%E3%83%9B%E3%83%B3/product-reviews/B07N6NRS8Q/ref=sr_1_1?sortBy=recent&language=zh_CN (Caused by SSLError(SSLError("bad handshake: SysCallError(10054, 'WSAECONNRESET')")))
2019-07-05 08:45:58,405 - root - ERROR - utils  - 161 - Amazon(https://www.amazon.co.jp/Liberty-Bluetooth-%E5%AE%8C%E5%85%A8%E3%83%AF%E3%82%A4%E3%83%A4%E3%83%AC%E3%82%B9%E3%82%A4%E3%83%A4%E3%83%9B%E3%83%B3-%E3%80%90%E6%9C%80%E5%A4%A724%E6%99%82%E9%96%93%E9%9F%B3%E6%A5%BD%E5%86%8D%E7%94%9F-IPX5%E9%98%B2%E6%B0%B4%E8%A6%8F%E6%A0%BC%E3%80%91/dp/B075SSLKDB/ref=sr_1_1)报错信息：请求失败
Traceback (most recent call last):
  File "C:\Users\hhh\AppData\Local\Programs\Python\Python37\lib\site-packages\urllib3\contrib\pyopenssl.py", line 453, in wrap_socket
    cnx.do_handshake()
  File "C:\Users\hhh\AppData\Local\Programs\Python\Python37\lib\site-packages\OpenSSL\SSL.py", line 1915, in do_handshake
    self._raise_ssl_error(self._ssl, result)
  File "C:\Users\hhh\AppData\Local\Programs\Python\Python37\lib\site-packages\OpenSSL\SSL.py", line 1639, in _raise_ssl_error
    raise SysCallError(errno, errorcode.get(errno))
OpenSSL.SSL.SysCallError: (10054, 'WSAECONNRESET')

During handling of the above exception, another exception occurred:

Traceback (most recent call last):
  File "C:\Users\hhh\AppData\Local\Programs\Python\Python37\lib\site-packages\urllib3\connectionpool.py", line 600, in urlopen
    chunked=chunked)
  File "C:\Users\hhh\AppData\Local\Programs\Python\Python37\lib\site-packages\urllib3\connectionpool.py", line 343, in _make_request
    self._validate_conn(conn)
  File "C:\Users\hhh\AppData\Local\Programs\Python\Python37\lib\site-packages\urllib3\connectionpool.py", line 839, in _validate_conn
    conn.connect()
  File "C:\Users\hhh\AppData\Local\Programs\Python\Python37\lib\site-packages\urllib3\connection.py", line 344, in connect
    ssl_context=context)
  File "C:\Users\hhh\AppData\Local\Programs\Python\Python37\lib\site-packages\urllib3\util\ssl_.py", line 344, in ssl_wrap_socket
    return context.wrap_socket(sock, server_hostname=server_hostname)
  File "C:\Users\hhh\AppData\Local\Programs\Python\Python37\lib\site-packages\urllib3\contrib\pyopenssl.py", line 459, in wrap_socket
    raise ssl.SSLError('bad handshake: %r' % e)
ssl.SSLError: ("bad handshake: SysCallError(10054, 'WSAECONNRESET')",)

During handling of the above exception, another exception occurred:

Traceback (most recent call last):
  File "C:\Users\hhh\AppData\Local\Programs\Python\Python37\lib\site-packages\requests\adapters.py", line 449, in send
    timeout=timeout
  File "C:\Users\hhh\AppData\Local\Programs\Python\Python37\lib\site-packages\urllib3\connectionpool.py", line 638, in urlopen
    _stacktrace=sys.exc_info()[2])
  File "C:\Users\hhh\AppData\Local\Programs\Python\Python37\lib\site-packages\urllib3\util\retry.py", line 398, in increment
    raise MaxRetryError(_pool, url, error or ResponseError(cause))
urllib3.exceptions.MaxRetryError: HTTPSConnectionPool(host='www.amazon.co.jp', port=443): Max retries exceeded with url: /Liberty-Bluetooth-%E5%AE%8C%E5%85%A8%E3%83%AF%E3%82%A4%E3%83%A4%E3%83%AC%E3%82%B9%E3%82%A4%E3%83%A4%E3%83%9B%E3%83%B3-%E3%80%90%E6%9C%80%E5%A4%A724%E6%99%82%E9%96%93%E9%9F%B3%E6%A5%BD%E5%86%8D%E7%94%9F-IPX5%E9%98%B2%E6%B0%B4%E8%A6%8F%E6%A0%BC%E3%80%91/product-reviews/B075SSLKDB/ref=sr_1_1?sortBy=recent&language=zh_CN (Caused by SSLError(SSLError("bad handshake: SysCallError(10054, 'WSAECONNRESET')")))

During handling of the above exception, another exception occurred:

Traceback (most recent call last):
  File "C:\Users\hhh\Desktop\Demo\reviews\amazon\amazon_review.py", line 228, in run
    review_html = self.parse_url(review_url)
  File "C:\Users\hhh\AppData\Local\Programs\Python\Python37\lib\site-packages\retrying.py", line 49, in wrapped_f
    return Retrying(*dargs, **dkw).call(f, *args, **kw)
  File "C:\Users\hhh\AppData\Local\Programs\Python\Python37\lib\site-packages\retrying.py", line 212, in call
    raise attempt.get()
  File "C:\Users\hhh\AppData\Local\Programs\Python\Python37\lib\site-packages\retrying.py", line 247, in get
    six.reraise(self.value[0], self.value[1], self.value[2])
  File "C:\Users\hhh\AppData\Local\Programs\Python\Python37\lib\site-packages\six.py", line 693, in reraise
    raise value
  File "C:\Users\hhh\AppData\Local\Programs\Python\Python37\lib\site-packages\retrying.py", line 200, in call
    attempt = Attempt(fn(*args, **kwargs), attempt_number, False)
  File "C:\Users\hhh\Desktop\Demo\reviews\amazon\amazon_review.py", line 38, in parse_url
    resp = requests.get(url, headers=self.headers, params=kw, timeout=100)
  File "C:\Users\hhh\AppData\Local\Programs\Python\Python37\lib\site-packages\requests\api.py", line 75, in get
    return request('get', url, params=params, **kwargs)
  File "C:\Users\hhh\AppData\Local\Programs\Python\Python37\lib\site-packages\requests\api.py", line 60, in request
    return session.request(method=method, url=url, **kwargs)
  File "C:\Users\hhh\AppData\Local\Programs\Python\Python37\lib\site-packages\requests\sessions.py", line 533, in request
    resp = self.send(prep, **send_kwargs)
  File "C:\Users\hhh\AppData\Local\Programs\Python\Python37\lib\site-packages\requests\sessions.py", line 646, in send
    r = adapter.send(request, **kwargs)
  File "C:\Users\hhh\AppData\Local\Programs\Python\Python37\lib\site-packages\requests\adapters.py", line 514, in send
    raise SSLError(e, request=request)
requests.exceptions.SSLError: HTTPSConnectionPool(host='www.amazon.co.jp', port=443): Max retries exceeded with url: /Liberty-Bluetooth-%E5%AE%8C%E5%85%A8%E3%83%AF%E3%82%A4%E3%83%A4%E3%83%AC%E3%82%B9%E3%82%A4%E3%83%A4%E3%83%9B%E3%83%B3-%E3%80%90%E6%9C%80%E5%A4%A724%E6%99%82%E9%96%93%E9%9F%B3%E6%A5%BD%E5%86%8D%E7%94%9F-IPX5%E9%98%B2%E6%B0%B4%E8%A6%8F%E6%A0%BC%E3%80%91/product-reviews/B075SSLKDB/ref=sr_1_1?sortBy=recent&language=zh_CN (Caused by SSLError(SSLError("bad handshake: SysCallError(10054, 'WSAECONNRESET')")))
2019-07-05 08:45:59,570 - root - ERROR - utils  - 161 - JD(100001667527)报错信息：数据库保存/更新失败
Traceback (most recent call last):
  File "C:\Users\hhh\Desktop\Demo\reviews\JD\jd_review.py", line 157, in save_data
    c.execute(sql)
cx_Oracle.IntegrityError: ORA-00001: 违反唯一约束条件 (EIP.ECOMMERCE_REVIEW_PIX3)
2019-07-05 08:45:59,577 - root - ERROR - utils  - 161 - JD(100001667527)报错信息：数据库保存/更新失败
Traceback (most recent call last):
  File "C:\Users\hhh\Desktop\Demo\reviews\JD\jd_review.py", line 157, in save_data
    c.execute(sql)
cx_Oracle.IntegrityError: ORA-00001: 违反唯一约束条件 (EIP.ECOMMERCE_REVIEW_PIX3)
2019-07-05 08:45:59,586 - root - ERROR - utils  - 161 - JD(100001667527)报错信息：数据库保存/更新失败
Traceback (most recent call last):
  File "C:\Users\hhh\Desktop\Demo\reviews\JD\jd_review.py", line 157, in save_data
    c.execute(sql)
cx_Oracle.IntegrityError: ORA-00001: 违反唯一约束条件 (EIP.ECOMMERCE_REVIEW_PIX3)
2019-07-05 08:45:59,593 - root - ERROR - utils  - 161 - JD(100001667527)报错信息：数据库保存/更新失败
Traceback (most recent call last):
  File "C:\Users\hhh\Desktop\Demo\reviews\JD\jd_review.py", line 157, in save_data
    c.execute(sql)
cx_Oracle.IntegrityError: ORA-00001: 违反唯一约束条件 (EIP.ECOMMERCE_REVIEW_PIX3)
2019-07-05 08:45:59,598 - root - ERROR - utils  - 161 - JD(100001667527)报错信息：数据库保存/更新失败
Traceback (most recent call last):
  File "C:\Users\hhh\Desktop\Demo\reviews\JD\jd_review.py", line 157, in save_data
    c.execute(sql)
cx_Oracle.IntegrityError: ORA-00001: 违反唯一约束条件 (EIP.ECOMMERCE_REVIEW_PIX3)
2019-07-05 08:45:59,603 - root - ERROR - utils  - 161 - JD(100001667527)报错信息：数据库保存/更新失败
Traceback (most recent call last):
  File "C:\Users\hhh\Desktop\Demo\reviews\JD\jd_review.py", line 157, in save_data
    c.execute(sql)
cx_Oracle.IntegrityError: ORA-00001: 违反唯一约束条件 (EIP.ECOMMERCE_REVIEW_PIX3)
2019-07-05 08:45:59,610 - root - ERROR - utils  - 161 - JD(100001667527)报错信息：数据库保存/更新失败
Traceback (most recent call last):
  File "C:\Users\hhh\Desktop\Demo\reviews\JD\jd_review.py", line 157, in save_data
    c.execute(sql)
cx_Oracle.IntegrityError: ORA-00001: 违反唯一约束条件 (EIP.ECOMMERCE_REVIEW_PIX3)
2019-07-05 08:45:59,615 - root - ERROR - utils  - 161 - JD(100001667527)报错信息：数据库保存/更新失败
Traceback (most recent call last):
  File "C:\Users\hhh\Desktop\Demo\reviews\JD\jd_review.py", line 157, in save_data
    c.execute(sql)
cx_Oracle.IntegrityError: ORA-00001: 违反唯一约束条件 (EIP.ECOMMERCE_REVIEW_PIX3)
2019-07-05 08:45:59,627 - root - ERROR - utils  - 161 - JD(100001667527)报错信息：数据库保存/更新失败
Traceback (most recent call last):
  File "C:\Users\hhh\Desktop\Demo\reviews\JD\jd_review.py", line 157, in save_data
    c.execute(sql)
cx_Oracle.IntegrityError: ORA-00001: 违反唯一约束条件 (EIP.ECOMMERCE_REVIEW_PIX3)
2019-07-05 08:45:59,632 - root - ERROR - utils  - 161 - JD(100001667527)报错信息：数据库保存/更新失败
Traceback (most recent call last):
  File "C:\Users\hhh\Desktop\Demo\reviews\JD\jd_review.py", line 157, in save_data
    c.execute(sql)
cx_Oracle.IntegrityError: ORA-00001: 违反唯一约束条件 (EIP.ECOMMERCE_REVIEW_PIX3)
2019-07-05 08:45:59,638 - root - ERROR - utils  - 161 - JD(100001667527)报错信息：数据库保存/更新失败
Traceback (most recent call last):
  File "C:\Users\hhh\Desktop\Demo\reviews\JD\jd_review.py", line 157, in save_data
    c.execute(sql)
cx_Oracle.IntegrityError: ORA-00001: 违反唯一约束条件 (EIP.ECOMMERCE_REVIEW_PIX3)
2019-07-05 08:45:59,649 - root - ERROR - utils  - 161 - JD(100001667527)报错信息：数据库保存/更新失败
Traceback (most recent call last):
  File "C:\Users\hhh\Desktop\Demo\reviews\JD\jd_review.py", line 157, in save_data
    c.execute(sql)
cx_Oracle.IntegrityError: ORA-00001: 违反唯一约束条件 (EIP.ECOMMERCE_REVIEW_PIX3)
2019-07-05 08:45:59,655 - root - ERROR - utils  - 161 - JD(100001667527)报错信息：数据库保存/更新失败
Traceback (most recent call last):
  File "C:\Users\hhh\Desktop\Demo\reviews\JD\jd_review.py", line 157, in save_data
    c.execute(sql)
cx_Oracle.IntegrityError: ORA-00001: 违反唯一约束条件 (EIP.ECOMMERCE_REVIEW_PIX3)
2019-07-05 08:45:59,660 - root - ERROR - utils  - 161 - JD(100001667527)报错信息：数据库保存/更新失败
Traceback (most recent call last):
  File "C:\Users\hhh\Desktop\Demo\reviews\JD\jd_review.py", line 157, in save_data
    c.execute(sql)
cx_Oracle.IntegrityError: ORA-00001: 违反唯一约束条件 (EIP.ECOMMERCE_REVIEW_PIX3)
2019-07-05 08:45:59,667 - root - ERROR - utils  - 161 - JD(100001667527)报错信息：数据库保存/更新失败
Traceback (most recent call last):
  File "C:\Users\hhh\Desktop\Demo\reviews\JD\jd_review.py", line 157, in save_data
    c.execute(sql)
cx_Oracle.IntegrityError: ORA-00001: 违反唯一约束条件 (EIP.ECOMMERCE_REVIEW_PIX3)
2019-07-05 08:45:59,673 - root - ERROR - utils  - 161 - JD(100001667527)报错信息：数据库保存/更新失败
Traceback (most recent call last):
  File "C:\Users\hhh\Desktop\Demo\reviews\JD\jd_review.py", line 157, in save_data
    c.execute(sql)
cx_Oracle.IntegrityError: ORA-00001: 违反唯一约束条件 (EIP.ECOMMERCE_REVIEW_PIX3)
2019-07-05 08:45:59,678 - root - ERROR - utils  - 161 - JD(100001667527)报错信息：数据库保存/更新失败
Traceback (most recent call last):
  File "C:\Users\hhh\Desktop\Demo\reviews\JD\jd_review.py", line 157, in save_data
    c.execute(sql)
cx_Oracle.IntegrityError: ORA-00001: 违反唯一约束条件 (EIP.ECOMMERCE_REVIEW_PIX3)
2019-07-05 08:45:59,684 - root - ERROR - utils  - 161 - JD(100001667527)报错信息：数据库保存/更新失败
Traceback (most recent call last):
  File "C:\Users\hhh\Desktop\Demo\reviews\JD\jd_review.py", line 157, in save_data
    c.execute(sql)
cx_Oracle.IntegrityError: ORA-00001: 违反唯一约束条件 (EIP.ECOMMERCE_REVIEW_PIX3)
2019-07-05 08:45:59,697 - root - ERROR - utils  - 161 - JD(100001667527)报错信息：数据库保存/更新失败
Traceback (most recent call last):
  File "C:\Users\hhh\Desktop\Demo\reviews\JD\jd_review.py", line 157, in save_data
    c.execute(sql)
cx_Oracle.IntegrityError: ORA-00001: 违反唯一约束条件 (EIP.ECOMMERCE_REVIEW_PIX3)
2019-07-05 08:45:59,710 - root - ERROR - utils  - 161 - JD(100001667527)报错信息：数据库保存/更新失败
Traceback (most recent call last):
  File "C:\Users\hhh\Desktop\Demo\reviews\JD\jd_review.py", line 157, in save_data
    c.execute(sql)
cx_Oracle.IntegrityError: ORA-00001: 违反唯一约束条件 (EIP.ECOMMERCE_REVIEW_PIX3)
2019-07-05 08:45:59,719 - root - ERROR - utils  - 161 - JD(100001667527)报错信息：数据库保存/更新失败
Traceback (most recent call last):
  File "C:\Users\hhh\Desktop\Demo\reviews\JD\jd_review.py", line 157, in save_data
    c.execute(sql)
cx_Oracle.IntegrityError: ORA-00001: 违反唯一约束条件 (EIP.ECOMMERCE_REVIEW_PIX3)
2019-07-05 08:45:59,725 - root - ERROR - utils  - 161 - JD(100001667527)报错信息：数据库保存/更新失败
Traceback (most recent call last):
  File "C:\Users\hhh\Desktop\Demo\reviews\JD\jd_review.py", line 157, in save_data
    c.execute(sql)
cx_Oracle.IntegrityError: ORA-00001: 违反唯一约束条件 (EIP.ECOMMERCE_REVIEW_PIX3)
2019-07-05 08:45:59,740 - root - ERROR - utils  - 161 - JD(100001667527)报错信息：数据库保存/更新失败
Traceback (most recent call last):
  File "C:\Users\hhh\Desktop\Demo\reviews\JD\jd_review.py", line 157, in save_data
    c.execute(sql)
cx_Oracle.IntegrityError: ORA-00001: 违反唯一约束条件 (EIP.ECOMMERCE_REVIEW_PIX3)
2019-07-05 08:45:59,751 - root - ERROR - utils  - 161 - JD(100001667527)报错信息：数据库保存/更新失败
Traceback (most recent call last):
  File "C:\Users\hhh\Desktop\Demo\reviews\JD\jd_review.py", line 157, in save_data
    c.execute(sql)
cx_Oracle.IntegrityError: ORA-00001: 违反唯一约束条件 (EIP.ECOMMERCE_REVIEW_PIX3)
2019-07-05 08:45:59,758 - root - ERROR - utils  - 161 - JD(100001667527)报错信息：数据库保存/更新失败
Traceback (most recent call last):
  File "C:\Users\hhh\Desktop\Demo\reviews\JD\jd_review.py", line 157, in save_data
    c.execute(sql)
cx_Oracle.IntegrityError: ORA-00001: 违反唯一约束条件 (EIP.ECOMMERCE_REVIEW_PIX3)
2019-07-05 08:45:59,764 - root - ERROR - utils  - 161 - JD(100001667527)报错信息：数据库保存/更新失败
Traceback (most recent call last):
  File "C:\Users\hhh\Desktop\Demo\reviews\JD\jd_review.py", line 157, in save_data
    c.execute(sql)
cx_Oracle.IntegrityError: ORA-00001: 违反唯一约束条件 (EIP.ECOMMERCE_REVIEW_PIX3)
2019-07-05 08:45:59,770 - root - ERROR - utils  - 161 - JD(100001667527)报错信息：数据库保存/更新失败
Traceback (most recent call last):
  File "C:\Users\hhh\Desktop\Demo\reviews\JD\jd_review.py", line 157, in save_data
    c.execute(sql)
cx_Oracle.IntegrityError: ORA-00001: 违反唯一约束条件 (EIP.ECOMMERCE_REVIEW_PIX3)
2019-07-05 08:45:59,779 - root - ERROR - utils  - 161 - JD(100001667527)报错信息：数据库保存/更新失败
Traceback (most recent call last):
  File "C:\Users\hhh\Desktop\Demo\reviews\JD\jd_review.py", line 157, in save_data
    c.execute(sql)
cx_Oracle.IntegrityError: ORA-00001: 违反唯一约束条件 (EIP.ECOMMERCE_REVIEW_PIX3)
2019-07-05 08:45:59,787 - root - ERROR - utils  - 161 - JD(100001667527)报错信息：数据库保存/更新失败
Traceback (most recent call last):
  File "C:\Users\hhh\Desktop\Demo\reviews\JD\jd_review.py", line 157, in save_data
    c.execute(sql)
cx_Oracle.IntegrityError: ORA-00001: 违反唯一约束条件 (EIP.ECOMMERCE_REVIEW_PIX3)
2019-07-05 08:46:09,643 - root - ERROR - utils  - 161 - JD(100002361195)报错信息：数据库保存/更新失败
Traceback (most recent call last):
  File "C:\Users\hhh\Desktop\Demo\reviews\JD\jd_review.py", line 157, in save_data
    c.execute(sql)
cx_Oracle.IntegrityError: ORA-00001: 违反唯一约束条件 (EIP.ECOMMERCE_REVIEW_PIX3)
2019-07-05 08:46:09,658 - root - ERROR - utils  - 161 - JD(100002361195)报错信息：数据库保存/更新失败
Traceback (most recent call last):
  File "C:\Users\hhh\Desktop\Demo\reviews\JD\jd_review.py", line 157, in save_data
    c.execute(sql)
cx_Oracle.IntegrityError: ORA-00001: 违反唯一约束条件 (EIP.ECOMMERCE_REVIEW_PIX3)
2019-07-05 08:46:09,668 - root - ERROR - utils  - 161 - JD(100002361195)报错信息：数据库保存/更新失败
Traceback (most recent call last):
  File "C:\Users\hhh\Desktop\Demo\reviews\JD\jd_review.py", line 157, in save_data
    c.execute(sql)
cx_Oracle.IntegrityError: ORA-00001: 违反唯一约束条件 (EIP.ECOMMERCE_REVIEW_PIX3)
2019-07-05 08:46:09,674 - root - ERROR - utils  - 161 - JD(100002361195)报错信息：数据库保存/更新失败
Traceback (most recent call last):
  File "C:\Users\hhh\Desktop\Demo\reviews\JD\jd_review.py", line 157, in save_data
    c.execute(sql)
cx_Oracle.IntegrityError: ORA-00001: 违反唯一约束条件 (EIP.ECOMMERCE_REVIEW_PIX3)
2019-07-05 08:46:09,681 - root - ERROR - utils  - 161 - JD(100002361195)报错信息：数据库保存/更新失败
Traceback (most recent call last):
  File "C:\Users\hhh\Desktop\Demo\reviews\JD\jd_review.py", line 157, in save_data
    c.execute(sql)
cx_Oracle.IntegrityError: ORA-00001: 违反唯一约束条件 (EIP.ECOMMERCE_REVIEW_PIX3)
2019-07-05 08:46:09,687 - root - ERROR - utils  - 161 - JD(100002361195)报错信息：数据库保存/更新失败
Traceback (most recent call last):
  File "C:\Users\hhh\Desktop\Demo\reviews\JD\jd_review.py", line 157, in save_data
    c.execute(sql)
cx_Oracle.IntegrityError: ORA-00001: 违反唯一约束条件 (EIP.ECOMMERCE_REVIEW_PIX3)
2019-07-05 08:46:09,696 - root - ERROR - utils  - 161 - JD(100002361195)报错信息：数据库保存/更新失败
Traceback (most recent call last):
  File "C:\Users\hhh\Desktop\Demo\reviews\JD\jd_review.py", line 157, in save_data
    c.execute(sql)
cx_Oracle.IntegrityError: ORA-00001: 违反唯一约束条件 (EIP.ECOMMERCE_REVIEW_PIX3)
2019-07-05 08:46:09,703 - root - ERROR - utils  - 161 - JD(100002361195)报错信息：数据库保存/更新失败
Traceback (most recent call last):
  File "C:\Users\hhh\Desktop\Demo\reviews\JD\jd_review.py", line 157, in save_data
    c.execute(sql)
cx_Oracle.IntegrityError: ORA-00001: 违反唯一约束条件 (EIP.ECOMMERCE_REVIEW_PIX3)
2019-07-05 08:47:01,008 - root - ERROR - utils  - 161 - Amazon(https://www.amazon.co.jp/%E3%82%BD%E3%83%95%E3%83%88%E3%83%90%E3%83%B3%E3%82%AF%E3%82%BB%E3%83%AC%E3%82%AF%E3%82%B7%E3%83%A7%E3%83%B3-Bluetooth%E3%82%A4%E3%83%A4%E3%83%9B%E3%83%B3%EF%BC%88%E3%83%96%E3%83%A9%E3%83%83%E3%82%AF%EF%BC%89SoftBank-GLIDiC-SB-WS72-MRTW-BK/dp/B07KNK8XCP/ref=sr_1_1)报错信息：请求失败
Traceback (most recent call last):
  File "C:\Users\hhh\AppData\Local\Programs\Python\Python37\lib\site-packages\urllib3\contrib\pyopenssl.py", line 453, in wrap_socket
    cnx.do_handshake()
  File "C:\Users\hhh\AppData\Local\Programs\Python\Python37\lib\site-packages\OpenSSL\SSL.py", line 1915, in do_handshake
    self._raise_ssl_error(self._ssl, result)
  File "C:\Users\hhh\AppData\Local\Programs\Python\Python37\lib\site-packages\OpenSSL\SSL.py", line 1639, in _raise_ssl_error
    raise SysCallError(errno, errorcode.get(errno))
OpenSSL.SSL.SysCallError: (10054, 'WSAECONNRESET')

During handling of the above exception, another exception occurred:

Traceback (most recent call last):
  File "C:\Users\hhh\AppData\Local\Programs\Python\Python37\lib\site-packages\urllib3\connectionpool.py", line 600, in urlopen
    chunked=chunked)
  File "C:\Users\hhh\AppData\Local\Programs\Python\Python37\lib\site-packages\urllib3\connectionpool.py", line 343, in _make_request
    self._validate_conn(conn)
  File "C:\Users\hhh\AppData\Local\Programs\Python\Python37\lib\site-packages\urllib3\connectionpool.py", line 839, in _validate_conn
    conn.connect()
  File "C:\Users\hhh\AppData\Local\Programs\Python\Python37\lib\site-packages\urllib3\connection.py", line 344, in connect
    ssl_context=context)
  File "C:\Users\hhh\AppData\Local\Programs\Python\Python37\lib\site-packages\urllib3\util\ssl_.py", line 344, in ssl_wrap_socket
    return context.wrap_socket(sock, server_hostname=server_hostname)
  File "C:\Users\hhh\AppData\Local\Programs\Python\Python37\lib\site-packages\urllib3\contrib\pyopenssl.py", line 459, in wrap_socket
    raise ssl.SSLError('bad handshake: %r' % e)
ssl.SSLError: ("bad handshake: SysCallError(10054, 'WSAECONNRESET')",)

During handling of the above exception, another exception occurred:

Traceback (most recent call last):
  File "C:\Users\hhh\AppData\Local\Programs\Python\Python37\lib\site-packages\requests\adapters.py", line 449, in send
    timeout=timeout
  File "C:\Users\hhh\AppData\Local\Programs\Python\Python37\lib\site-packages\urllib3\connectionpool.py", line 638, in urlopen
    _stacktrace=sys.exc_info()[2])
  File "C:\Users\hhh\AppData\Local\Programs\Python\Python37\lib\site-packages\urllib3\util\retry.py", line 398, in increment
    raise MaxRetryError(_pool, url, error or ResponseError(cause))
urllib3.exceptions.MaxRetryError: HTTPSConnectionPool(host='www.amazon.co.jp', port=443): Max retries exceeded with url: /%E3%82%BD%E3%83%95%E3%83%88%E3%83%90%E3%83%B3%E3%82%AF%E3%82%BB%E3%83%AC%E3%82%AF%E3%82%B7%E3%83%A7%E3%83%B3-Bluetooth%E3%82%A4%E3%83%A4%E3%83%9B%E3%83%B3%EF%BC%88%E3%83%96%E3%83%A9%E3%83%83%E3%82%AF%EF%BC%89SoftBank-GLIDiC-SB-WS72-MRTW-BK/product-reviews/B07KNK8XCP/ref=sr_1_1?sortBy=recent&language=zh_CN (Caused by SSLError(SSLError("bad handshake: SysCallError(10054, 'WSAECONNRESET')")))

During handling of the above exception, another exception occurred:

Traceback (most recent call last):
  File "C:\Users\hhh\Desktop\Demo\reviews\amazon\amazon_review.py", line 228, in run
    review_html = self.parse_url(review_url)
  File "C:\Users\hhh\AppData\Local\Programs\Python\Python37\lib\site-packages\retrying.py", line 49, in wrapped_f
    return Retrying(*dargs, **dkw).call(f, *args, **kw)
  File "C:\Users\hhh\AppData\Local\Programs\Python\Python37\lib\site-packages\retrying.py", line 212, in call
    raise attempt.get()
  File "C:\Users\hhh\AppData\Local\Programs\Python\Python37\lib\site-packages\retrying.py", line 247, in get
    six.reraise(self.value[0], self.value[1], self.value[2])
  File "C:\Users\hhh\AppData\Local\Programs\Python\Python37\lib\site-packages\six.py", line 693, in reraise
    raise value
  File "C:\Users\hhh\AppData\Local\Programs\Python\Python37\lib\site-packages\retrying.py", line 200, in call
    attempt = Attempt(fn(*args, **kwargs), attempt_number, False)
  File "C:\Users\hhh\Desktop\Demo\reviews\amazon\amazon_review.py", line 38, in parse_url
    resp = requests.get(url, headers=self.headers, params=kw, timeout=100)
  File "C:\Users\hhh\AppData\Local\Programs\Python\Python37\lib\site-packages\requests\api.py", line 75, in get
    return request('get', url, params=params, **kwargs)
  File "C:\Users\hhh\AppData\Local\Programs\Python\Python37\lib\site-packages\requests\api.py", line 60, in request
    return session.request(method=method, url=url, **kwargs)
  File "C:\Users\hhh\AppData\Local\Programs\Python\Python37\lib\site-packages\requests\sessions.py", line 533, in request
    resp = self.send(prep, **send_kwargs)
  File "C:\Users\hhh\AppData\Local\Programs\Python\Python37\lib\site-packages\requests\sessions.py", line 646, in send
    r = adapter.send(request, **kwargs)
  File "C:\Users\hhh\AppData\Local\Programs\Python\Python37\lib\site-packages\requests\adapters.py", line 514, in send
    raise SSLError(e, request=request)
requests.exceptions.SSLError: HTTPSConnectionPool(host='www.amazon.co.jp', port=443): Max retries exceeded with url: /%E3%82%BD%E3%83%95%E3%83%88%E3%83%90%E3%83%B3%E3%82%AF%E3%82%BB%E3%83%AC%E3%82%AF%E3%82%B7%E3%83%A7%E3%83%B3-Bluetooth%E3%82%A4%E3%83%A4%E3%83%9B%E3%83%B3%EF%BC%88%E3%83%96%E3%83%A9%E3%83%83%E3%82%AF%EF%BC%89SoftBank-GLIDiC-SB-WS72-MRTW-BK/product-reviews/B07KNK8XCP/ref=sr_1_1?sortBy=recent&language=zh_CN (Caused by SSLError(SSLError("bad handshake: SysCallError(10054, 'WSAECONNRESET')")))
2019-07-05 08:47:26,786 - root - ERROR - utils  - 161 - tmall(552634156539)报错信息：发送请求,进入评论页面失败
Traceback (most recent call last):
  File "C:\Users\hhh\Desktop\Demo\reviews\TMALL\tmall_review.py", line 205, in run
    self.enter_review()  # 发送请求,进入评论页面
  File "C:\Users\hhh\Desktop\Demo\reviews\TMALL\tmall_review.py", line 63, in enter_review
    self.order_time()
  File "C:\Users\hhh\Desktop\Demo\reviews\TMALL\tmall_review.py", line 102, in order_time
    element_artist[1].click()
  File "C:\Users\hhh\AppData\Local\Programs\Python\Python37\lib\site-packages\selenium\webdriver\remote\webelement.py", line 80, in click
    self._execute(Command.CLICK_ELEMENT)
  File "C:\Users\hhh\AppData\Local\Programs\Python\Python37\lib\site-packages\selenium\webdriver\remote\webelement.py", line 633, in _execute
    return self._parent.execute(command, params)
  File "C:\Users\hhh\AppData\Local\Programs\Python\Python37\lib\site-packages\selenium\webdriver\remote\webdriver.py", line 321, in execute
    self.error_handler.check_response(response)
  File "C:\Users\hhh\AppData\Local\Programs\Python\Python37\lib\site-packages\selenium\webdriver\remote\errorhandler.py", line 242, in check_response
    raise exception_class(message, screen, stacktrace)
selenium.common.exceptions.ElementNotVisibleException: Message: element not interactable
  (Session info: chrome=75.0.3770.100)
  (Driver info: chromedriver=74.0.3729.6 (255758eccf3d244491b8a1317aa76e1ce10d57e9-refs/branch-heads/3729@{#29}),platform=Windows NT 10.0.17763 x86_64)

