2019-06-26 10:22:12,025 - root - ERROR - utils  - 148 - tmall(587390513906)报错信息：发送请求,进入评论页面失败
Traceback (most recent call last):
  File "C:\Users\BruceChen\Desktop\Demo\reviews\TMALL\tmall_review.py", line 190, in run
    self.enter_review()  # 发送请求,进入评论页面
  File "C:\Users\BruceChen\Desktop\Demo\reviews\TMALL\tmall_review.py", line 50, in enter_review
    self.parse_url()
  File "C:\Python36-32\lib\site-packages\retrying.py", line 49, in wrapped_f
    return Retrying(*dargs, **dkw).call(f, *args, **kw)
  File "C:\Python36-32\lib\site-packages\retrying.py", line 212, in call
    raise attempt.get()
  File "C:\Python36-32\lib\site-packages\retrying.py", line 247, in get
    six.reraise(self.value[0], self.value[1], self.value[2])
  File "C:\Python36-32\lib\site-packages\six.py", line 693, in reraise
    raise value
  File "C:\Python36-32\lib\site-packages\retrying.py", line 200, in call
    attempt = Attempt(fn(*args, **kwargs), attempt_number, False)
  File "C:\Users\BruceChen\Desktop\Demo\reviews\TMALL\tmall_review.py", line 43, in parse_url
    status = getHttpStatus(self.driver)
  File "C:\Users\BruceChen\Desktop\Demo\reviews\TMALL\selenium_status.py", line 10, in getHttpStatus
    for responseReceived in browser.get_log('performance'):
  File "C:\Python36-32\lib\site-packages\selenium\webdriver\remote\webdriver.py", line 1262, in get_log
    return self.execute(Command.GET_LOG, {'type': log_type})['value']
  File "C:\Python36-32\lib\site-packages\selenium\webdriver\remote\webdriver.py", line 321, in execute
    self.error_handler.check_response(response)
  File "C:\Python36-32\lib\site-packages\selenium\webdriver\remote\errorhandler.py", line 242, in check_response
    raise exception_class(message, screen, stacktrace)
selenium.common.exceptions.InvalidArgumentException: Message: invalid argument: log type 'performance' not found
  (Session info: chrome=75.0.3770.100)

2019-06-26 10:22:54,625 - root - ERROR - utils  - 148 - tmall(590865770191)报错信息：发送请求,进入评论页面失败
Traceback (most recent call last):
  File "C:\Users\BruceChen\Desktop\Demo\reviews\TMALL\tmall_review.py", line 190, in run
    self.enter_review()  # 发送请求,进入评论页面
  File "C:\Users\BruceChen\Desktop\Demo\reviews\TMALL\tmall_review.py", line 50, in enter_review
    self.parse_url()
  File "C:\Python36-32\lib\site-packages\retrying.py", line 49, in wrapped_f
    return Retrying(*dargs, **dkw).call(f, *args, **kw)
  File "C:\Python36-32\lib\site-packages\retrying.py", line 212, in call
    raise attempt.get()
  File "C:\Python36-32\lib\site-packages\retrying.py", line 247, in get
    six.reraise(self.value[0], self.value[1], self.value[2])
  File "C:\Python36-32\lib\site-packages\six.py", line 693, in reraise
    raise value
  File "C:\Python36-32\lib\site-packages\retrying.py", line 200, in call
    attempt = Attempt(fn(*args, **kwargs), attempt_number, False)
  File "C:\Users\BruceChen\Desktop\Demo\reviews\TMALL\tmall_review.py", line 43, in parse_url
    status = getHttpStatus(self.driver)
  File "C:\Users\BruceChen\Desktop\Demo\reviews\TMALL\selenium_status.py", line 10, in getHttpStatus
    for responseReceived in browser.get_log('performance'):
  File "C:\Python36-32\lib\site-packages\selenium\webdriver\remote\webdriver.py", line 1262, in get_log
    return self.execute(Command.GET_LOG, {'type': log_type})['value']
  File "C:\Python36-32\lib\site-packages\selenium\webdriver\remote\webdriver.py", line 321, in execute
    self.error_handler.check_response(response)
  File "C:\Python36-32\lib\site-packages\selenium\webdriver\remote\errorhandler.py", line 242, in check_response
    raise exception_class(message, screen, stacktrace)
selenium.common.exceptions.InvalidArgumentException: Message: invalid argument: log type 'performance' not found
  (Session info: chrome=75.0.3770.100)

2019-06-26 10:23:37,272 - root - ERROR - utils  - 148 - tmall(528515320283)报错信息：发送请求,进入评论页面失败
Traceback (most recent call last):
  File "C:\Users\BruceChen\Desktop\Demo\reviews\TMALL\tmall_review.py", line 190, in run
    self.enter_review()  # 发送请求,进入评论页面
  File "C:\Users\BruceChen\Desktop\Demo\reviews\TMALL\tmall_review.py", line 50, in enter_review
    self.parse_url()
  File "C:\Python36-32\lib\site-packages\retrying.py", line 49, in wrapped_f
    return Retrying(*dargs, **dkw).call(f, *args, **kw)
  File "C:\Python36-32\lib\site-packages\retrying.py", line 212, in call
    raise attempt.get()
  File "C:\Python36-32\lib\site-packages\retrying.py", line 247, in get
    six.reraise(self.value[0], self.value[1], self.value[2])
  File "C:\Python36-32\lib\site-packages\six.py", line 693, in reraise
    raise value
  File "C:\Python36-32\lib\site-packages\retrying.py", line 200, in call
    attempt = Attempt(fn(*args, **kwargs), attempt_number, False)
  File "C:\Users\BruceChen\Desktop\Demo\reviews\TMALL\tmall_review.py", line 43, in parse_url
    status = getHttpStatus(self.driver)
  File "C:\Users\BruceChen\Desktop\Demo\reviews\TMALL\selenium_status.py", line 10, in getHttpStatus
    for responseReceived in browser.get_log('performance'):
  File "C:\Python36-32\lib\site-packages\selenium\webdriver\remote\webdriver.py", line 1262, in get_log
    return self.execute(Command.GET_LOG, {'type': log_type})['value']
  File "C:\Python36-32\lib\site-packages\selenium\webdriver\remote\webdriver.py", line 321, in execute
    self.error_handler.check_response(response)
  File "C:\Python36-32\lib\site-packages\selenium\webdriver\remote\errorhandler.py", line 242, in check_response
    raise exception_class(message, screen, stacktrace)
selenium.common.exceptions.InvalidArgumentException: Message: invalid argument: log type 'performance' not found
  (Session info: chrome=75.0.3770.100)

