2019-07-09 17:06:45,363 - root - INFO - Amazon,无url信息或传入参数格式不是列表
2019-07-09 17:06:45,363 - root - INFO - BestBuy,无url信息或传入参数格式不是列表
2019-07-09 17:06:45,364 - root - INFO - JD,无url信息或传入参数格式不是列表
2019-07-09 17:06:45,364 - root - INFO - Tmall,无url信息或传入参数格式不是列表
2019-07-09 17:07:09,217 - root - INFO - amazon,B07G5RKF3W共更新了0条,
2019-07-09 17:07:11,570 - root - INFO - amazon,B06XGBPW3D共更新了0条,
2019-07-09 17:07:14,051 - root - INFO - amazon,B074NBSF9N共更新了0条,
2019-07-09 17:07:16,370 - root - INFO - amazon,B00SAYCXWG共更新了0条,
2019-07-09 17:07:18,567 - root - INFO - amazon,B072DRCM1Q共更新了0条,
2019-07-09 17:07:20,930 - root - INFO - amazon,B06Y3YN2C8共更新了0条,
2019-07-09 17:07:22,870 - root - INFO - amazon,B06XGBPW3D共更新了0条,
2019-07-09 17:07:24,784 - root - INFO - amazon,B07GKHYVM8共更新了0条,
2019-07-09 17:07:27,221 - root - INFO - amazon,B01MQWUXZS共更新了0条,
2019-07-09 17:07:29,113 - root - INFO - amazon,B0749CW8X6共更新了0条,
2019-07-09 17:07:31,174 - root - INFO - amazon,B07MCGZK3B共更新了0条,
2019-07-09 17:07:31,452 - root - ERROR - Amazon(https://www.amazon.co.jp/Zero-Audio-TWZ-1000-%E5%AE%8C%E5%85%A8%E3%83%AF%E3%82%A4%E3%83%A4%E3%83%AC%E3%82%B9%E3%82%B9%E3%83%86%E3%83%AC%E3%82%AA%E3%83%98%E3%83%83%E3%83%89%E3%83%9B%E3%83%B3/dp/B07N6NRS8Q/ref=sr_1_1)报错信息：请求失败
Traceback (most recent call last):
  File "C:\Users\hhh\AppData\Local\Programs\Python\Python37\lib\site-packages\urllib3\contrib\pyopenssl.py", line 453, in wrap_socket
    cnx.do_handshake()
  File "C:\Users\hhh\AppData\Local\Programs\Python\Python37\lib\site-packages\OpenSSL\SSL.py", line 1915, in do_handshake
    self._raise_ssl_error(self._ssl, result)
  File "C:\Users\hhh\AppData\Local\Programs\Python\Python37\lib\site-packages\OpenSSL\SSL.py", line 1639, in _raise_ssl_error
    raise SysCallError(errno, errorcode.get(errno))
OpenSSL.SSL.SysCallError: (10054, 'WSAECONNRESET')

During handling of the above exception, another exception occurred:

Traceback (most recent call last):
  File "C:\Users\hhh\AppData\Local\Programs\Python\Python37\lib\site-packages\urllib3\connectionpool.py", line 600, in urlopen
    chunked=chunked)
  File "C:\Users\hhh\AppData\Local\Programs\Python\Python37\lib\site-packages\urllib3\connectionpool.py", line 343, in _make_request
    self._validate_conn(conn)
  File "C:\Users\hhh\AppData\Local\Programs\Python\Python37\lib\site-packages\urllib3\connectionpool.py", line 839, in _validate_conn
    conn.connect()
  File "C:\Users\hhh\AppData\Local\Programs\Python\Python37\lib\site-packages\urllib3\connection.py", line 344, in connect
    ssl_context=context)
  File "C:\Users\hhh\AppData\Local\Programs\Python\Python37\lib\site-packages\urllib3\util\ssl_.py", line 344, in ssl_wrap_socket
    return context.wrap_socket(sock, server_hostname=server_hostname)
  File "C:\Users\hhh\AppData\Local\Programs\Python\Python37\lib\site-packages\urllib3\contrib\pyopenssl.py", line 459, in wrap_socket
    raise ssl.SSLError('bad handshake: %r' % e)
ssl.SSLError: ("bad handshake: SysCallError(10054, 'WSAECONNRESET')",)

During handling of the above exception, another exception occurred:

Traceback (most recent call last):
  File "C:\Users\hhh\AppData\Local\Programs\Python\Python37\lib\site-packages\requests\adapters.py", line 449, in send
    timeout=timeout
  File "C:\Users\hhh\AppData\Local\Programs\Python\Python37\lib\site-packages\urllib3\connectionpool.py", line 638, in urlopen
    _stacktrace=sys.exc_info()[2])
  File "C:\Users\hhh\AppData\Local\Programs\Python\Python37\lib\site-packages\urllib3\util\retry.py", line 398, in increment
    raise MaxRetryError(_pool, url, error or ResponseError(cause))
urllib3.exceptions.MaxRetryError: HTTPSConnectionPool(host='www.amazon.co.jp', port=443): Max retries exceeded with url: /Zero-Audio-TWZ-1000-%E5%AE%8C%E5%85%A8%E3%83%AF%E3%82%A4%E3%83%A4%E3%83%AC%E3%82%B9%E3%82%B9%E3%83%86%E3%83%AC%E3%82%AA%E3%83%98%E3%83%83%E3%83%89%E3%83%9B%E3%83%B3/product-reviews/B07N6NRS8Q/ref=sr_1_1?sortBy=recent&language=zh_CN (Caused by SSLError(SSLError("bad handshake: SysCallError(10054, 'WSAECONNRESET')")))

During handling of the above exception, another exception occurred:

Traceback (most recent call last):
  File "C:\Users\hhh\Desktop\Demo\reviews\amazon\amazon_review.py", line 232, in run
    review_html = self.parse_url(review_url)
  File "C:\Users\hhh\AppData\Local\Programs\Python\Python37\lib\site-packages\retrying.py", line 49, in wrapped_f
    return Retrying(*dargs, **dkw).call(f, *args, **kw)
  File "C:\Users\hhh\AppData\Local\Programs\Python\Python37\lib\site-packages\retrying.py", line 212, in call
    raise attempt.get()
  File "C:\Users\hhh\AppData\Local\Programs\Python\Python37\lib\site-packages\retrying.py", line 247, in get
    six.reraise(self.value[0], self.value[1], self.value[2])
  File "C:\Users\hhh\AppData\Local\Programs\Python\Python37\lib\site-packages\six.py", line 693, in reraise
    raise value
  File "C:\Users\hhh\AppData\Local\Programs\Python\Python37\lib\site-packages\retrying.py", line 200, in call
    attempt = Attempt(fn(*args, **kwargs), attempt_number, False)
  File "C:\Users\hhh\Desktop\Demo\reviews\amazon\amazon_review.py", line 40, in parse_url
    resp = requests.get(url, headers=self.headers, params=kw, timeout=100)
  File "C:\Users\hhh\AppData\Local\Programs\Python\Python37\lib\site-packages\requests\api.py", line 75, in get
    return request('get', url, params=params, **kwargs)
  File "C:\Users\hhh\AppData\Local\Programs\Python\Python37\lib\site-packages\requests\api.py", line 60, in request
    return session.request(method=method, url=url, **kwargs)
  File "C:\Users\hhh\AppData\Local\Programs\Python\Python37\lib\site-packages\requests\sessions.py", line 533, in request
    resp = self.send(prep, **send_kwargs)
  File "C:\Users\hhh\AppData\Local\Programs\Python\Python37\lib\site-packages\requests\sessions.py", line 646, in send
    r = adapter.send(request, **kwargs)
  File "C:\Users\hhh\AppData\Local\Programs\Python\Python37\lib\site-packages\requests\adapters.py", line 514, in send
    raise SSLError(e, request=request)
requests.exceptions.SSLError: HTTPSConnectionPool(host='www.amazon.co.jp', port=443): Max retries exceeded with url: /Zero-Audio-TWZ-1000-%E5%AE%8C%E5%85%A8%E3%83%AF%E3%82%A4%E3%83%A4%E3%83%AC%E3%82%B9%E3%82%B9%E3%83%86%E3%83%AC%E3%82%AA%E3%83%98%E3%83%83%E3%83%89%E3%83%9B%E3%83%B3/product-reviews/B07N6NRS8Q/ref=sr_1_1?sortBy=recent&language=zh_CN (Caused by SSLError(SSLError("bad handshake: SysCallError(10054, 'WSAECONNRESET')")))
2019-07-09 17:07:33,677 - root - INFO - amazon,B07H314BYH共更新了0条,
2019-07-09 17:07:35,959 - root - INFO - amazon,B0748K7JW6共更新了1条,
2019-07-09 17:07:37,496 - root - INFO - amazon,B0749BX1X3共更新了1条,
2019-07-09 17:07:39,541 - root - INFO - amazon,B075JBP2P7共更新了0条,
2019-07-09 17:07:41,137 - root - INFO - amazon,B075JBP2P7共更新了0条,
2019-07-09 17:07:41,465 - root - ERROR - Amazon(https://www.amazon.co.jp/Liberty-Bluetooth-%E5%AE%8C%E5%85%A8%E3%83%AF%E3%82%A4%E3%83%A4%E3%83%AC%E3%82%B9%E3%82%A4%E3%83%A4%E3%83%9B%E3%83%B3-%E3%80%90%E6%9C%80%E5%A4%A724%E6%99%82%E9%96%93%E9%9F%B3%E6%A5%BD%E5%86%8D%E7%94%9F-IPX5%E9%98%B2%E6%B0%B4%E8%A6%8F%E6%A0%BC%E3%80%91/dp/B075SSLKDB/ref=sr_1_1)报错信息：请求失败
Traceback (most recent call last):
  File "C:\Users\hhh\AppData\Local\Programs\Python\Python37\lib\site-packages\urllib3\contrib\pyopenssl.py", line 453, in wrap_socket
    cnx.do_handshake()
  File "C:\Users\hhh\AppData\Local\Programs\Python\Python37\lib\site-packages\OpenSSL\SSL.py", line 1915, in do_handshake
    self._raise_ssl_error(self._ssl, result)
  File "C:\Users\hhh\AppData\Local\Programs\Python\Python37\lib\site-packages\OpenSSL\SSL.py", line 1639, in _raise_ssl_error
    raise SysCallError(errno, errorcode.get(errno))
OpenSSL.SSL.SysCallError: (10054, 'WSAECONNRESET')

During handling of the above exception, another exception occurred:

Traceback (most recent call last):
  File "C:\Users\hhh\AppData\Local\Programs\Python\Python37\lib\site-packages\urllib3\connectionpool.py", line 600, in urlopen
    chunked=chunked)
  File "C:\Users\hhh\AppData\Local\Programs\Python\Python37\lib\site-packages\urllib3\connectionpool.py", line 343, in _make_request
    self._validate_conn(conn)
  File "C:\Users\hhh\AppData\Local\Programs\Python\Python37\lib\site-packages\urllib3\connectionpool.py", line 839, in _validate_conn
    conn.connect()
  File "C:\Users\hhh\AppData\Local\Programs\Python\Python37\lib\site-packages\urllib3\connection.py", line 344, in connect
    ssl_context=context)
  File "C:\Users\hhh\AppData\Local\Programs\Python\Python37\lib\site-packages\urllib3\util\ssl_.py", line 344, in ssl_wrap_socket
    return context.wrap_socket(sock, server_hostname=server_hostname)
  File "C:\Users\hhh\AppData\Local\Programs\Python\Python37\lib\site-packages\urllib3\contrib\pyopenssl.py", line 459, in wrap_socket
    raise ssl.SSLError('bad handshake: %r' % e)
ssl.SSLError: ("bad handshake: SysCallError(10054, 'WSAECONNRESET')",)

During handling of the above exception, another exception occurred:

Traceback (most recent call last):
  File "C:\Users\hhh\AppData\Local\Programs\Python\Python37\lib\site-packages\requests\adapters.py", line 449, in send
    timeout=timeout
  File "C:\Users\hhh\AppData\Local\Programs\Python\Python37\lib\site-packages\urllib3\connectionpool.py", line 638, in urlopen
    _stacktrace=sys.exc_info()[2])
  File "C:\Users\hhh\AppData\Local\Programs\Python\Python37\lib\site-packages\urllib3\util\retry.py", line 398, in increment
    raise MaxRetryError(_pool, url, error or ResponseError(cause))
urllib3.exceptions.MaxRetryError: HTTPSConnectionPool(host='www.amazon.co.jp', port=443): Max retries exceeded with url: /Liberty-Bluetooth-%E5%AE%8C%E5%85%A8%E3%83%AF%E3%82%A4%E3%83%A4%E3%83%AC%E3%82%B9%E3%82%A4%E3%83%A4%E3%83%9B%E3%83%B3-%E3%80%90%E6%9C%80%E5%A4%A724%E6%99%82%E9%96%93%E9%9F%B3%E6%A5%BD%E5%86%8D%E7%94%9F-IPX5%E9%98%B2%E6%B0%B4%E8%A6%8F%E6%A0%BC%E3%80%91/product-reviews/B075SSLKDB/ref=sr_1_1?sortBy=recent&language=zh_CN (Caused by SSLError(SSLError("bad handshake: SysCallError(10054, 'WSAECONNRESET')")))

During handling of the above exception, another exception occurred:

Traceback (most recent call last):
  File "C:\Users\hhh\Desktop\Demo\reviews\amazon\amazon_review.py", line 232, in run
    review_html = self.parse_url(review_url)
  File "C:\Users\hhh\AppData\Local\Programs\Python\Python37\lib\site-packages\retrying.py", line 49, in wrapped_f
    return Retrying(*dargs, **dkw).call(f, *args, **kw)
  File "C:\Users\hhh\AppData\Local\Programs\Python\Python37\lib\site-packages\retrying.py", line 212, in call
    raise attempt.get()
  File "C:\Users\hhh\AppData\Local\Programs\Python\Python37\lib\site-packages\retrying.py", line 247, in get
    six.reraise(self.value[0], self.value[1], self.value[2])
  File "C:\Users\hhh\AppData\Local\Programs\Python\Python37\lib\site-packages\six.py", line 693, in reraise
    raise value
  File "C:\Users\hhh\AppData\Local\Programs\Python\Python37\lib\site-packages\retrying.py", line 200, in call
    attempt = Attempt(fn(*args, **kwargs), attempt_number, False)
  File "C:\Users\hhh\Desktop\Demo\reviews\amazon\amazon_review.py", line 40, in parse_url
    resp = requests.get(url, headers=self.headers, params=kw, timeout=100)
  File "C:\Users\hhh\AppData\Local\Programs\Python\Python37\lib\site-packages\requests\api.py", line 75, in get
    return request('get', url, params=params, **kwargs)
  File "C:\Users\hhh\AppData\Local\Programs\Python\Python37\lib\site-packages\requests\api.py", line 60, in request
    return session.request(method=method, url=url, **kwargs)
  File "C:\Users\hhh\AppData\Local\Programs\Python\Python37\lib\site-packages\requests\sessions.py", line 533, in request
    resp = self.send(prep, **send_kwargs)
  File "C:\Users\hhh\AppData\Local\Programs\Python\Python37\lib\site-packages\requests\sessions.py", line 646, in send
    r = adapter.send(request, **kwargs)
  File "C:\Users\hhh\AppData\Local\Programs\Python\Python37\lib\site-packages\requests\adapters.py", line 514, in send
    raise SSLError(e, request=request)
requests.exceptions.SSLError: HTTPSConnectionPool(host='www.amazon.co.jp', port=443): Max retries exceeded with url: /Liberty-Bluetooth-%E5%AE%8C%E5%85%A8%E3%83%AF%E3%82%A4%E3%83%A4%E3%83%AC%E3%82%B9%E3%82%A4%E3%83%A4%E3%83%9B%E3%83%B3-%E3%80%90%E6%9C%80%E5%A4%A724%E6%99%82%E9%96%93%E9%9F%B3%E6%A5%BD%E5%86%8D%E7%94%9F-IPX5%E9%98%B2%E6%B0%B4%E8%A6%8F%E6%A0%BC%E3%80%91/product-reviews/B075SSLKDB/ref=sr_1_1?sortBy=recent&language=zh_CN (Caused by SSLError(SSLError("bad handshake: SysCallError(10054, 'WSAECONNRESET')")))
2019-07-09 17:07:43,825 - root - INFO - amazon,B075JBP2P7共更新了0条,
2019-07-09 17:07:45,682 - root - INFO - amazon,B01N3AJ0ID共更新了0条,
2019-07-09 17:07:47,347 - root - INFO - amazon,B0711V7BV6共更新了0条,
2019-07-09 17:07:49,934 - root - INFO - amazon,B071S9RGB1共更新了0条,
2019-07-09 17:07:51,918 - root - INFO - amazon,B06Y3YNSMJ共更新了0条,
2019-07-09 17:07:53,839 - root - INFO - amazon,B01G3WBCQY共更新了0条,
2019-07-09 17:07:55,730 - root - INFO - amazon,B0756Z8X82共更新了0条,
2019-07-09 17:07:57,987 - root - INFO - amazon,B0753Z4PGC共更新了0条,
2019-07-09 17:08:00,713 - root - INFO - amazon,B078WRCW35共更新了1条,
2019-07-09 17:08:03,582 - root - INFO - amazon,B00Y839YMU共更新了0条,
2019-07-09 17:08:06,388 - root - INFO - amazon,B01KJL4XNY共更新了0条,
2019-07-09 17:08:06,691 - root - ERROR - Amazon(https://www.amazon.co.jp/%E3%82%BD%E3%83%95%E3%83%88%E3%83%90%E3%83%B3%E3%82%AF%E3%82%BB%E3%83%AC%E3%82%AF%E3%82%B7%E3%83%A7%E3%83%B3-Bluetooth%E3%82%A4%E3%83%A4%E3%83%9B%E3%83%B3%EF%BC%88%E3%83%96%E3%83%A9%E3%83%83%E3%82%AF%EF%BC%89SoftBank-GLIDiC-SB-WS72-MRTW-BK/dp/B07KNK8XCP/ref=sr_1_1)报错信息：请求失败
Traceback (most recent call last):
  File "C:\Users\hhh\AppData\Local\Programs\Python\Python37\lib\site-packages\urllib3\contrib\pyopenssl.py", line 453, in wrap_socket
    cnx.do_handshake()
  File "C:\Users\hhh\AppData\Local\Programs\Python\Python37\lib\site-packages\OpenSSL\SSL.py", line 1915, in do_handshake
    self._raise_ssl_error(self._ssl, result)
  File "C:\Users\hhh\AppData\Local\Programs\Python\Python37\lib\site-packages\OpenSSL\SSL.py", line 1639, in _raise_ssl_error
    raise SysCallError(errno, errorcode.get(errno))
OpenSSL.SSL.SysCallError: (10054, 'WSAECONNRESET')

During handling of the above exception, another exception occurred:

Traceback (most recent call last):
  File "C:\Users\hhh\AppData\Local\Programs\Python\Python37\lib\site-packages\urllib3\connectionpool.py", line 600, in urlopen
    chunked=chunked)
  File "C:\Users\hhh\AppData\Local\Programs\Python\Python37\lib\site-packages\urllib3\connectionpool.py", line 343, in _make_request
    self._validate_conn(conn)
  File "C:\Users\hhh\AppData\Local\Programs\Python\Python37\lib\site-packages\urllib3\connectionpool.py", line 839, in _validate_conn
    conn.connect()
  File "C:\Users\hhh\AppData\Local\Programs\Python\Python37\lib\site-packages\urllib3\connection.py", line 344, in connect
    ssl_context=context)
  File "C:\Users\hhh\AppData\Local\Programs\Python\Python37\lib\site-packages\urllib3\util\ssl_.py", line 344, in ssl_wrap_socket
    return context.wrap_socket(sock, server_hostname=server_hostname)
  File "C:\Users\hhh\AppData\Local\Programs\Python\Python37\lib\site-packages\urllib3\contrib\pyopenssl.py", line 459, in wrap_socket
    raise ssl.SSLError('bad handshake: %r' % e)
ssl.SSLError: ("bad handshake: SysCallError(10054, 'WSAECONNRESET')",)

During handling of the above exception, another exception occurred:

Traceback (most recent call last):
  File "C:\Users\hhh\AppData\Local\Programs\Python\Python37\lib\site-packages\requests\adapters.py", line 449, in send
    timeout=timeout
  File "C:\Users\hhh\AppData\Local\Programs\Python\Python37\lib\site-packages\urllib3\connectionpool.py", line 638, in urlopen
    _stacktrace=sys.exc_info()[2])
  File "C:\Users\hhh\AppData\Local\Programs\Python\Python37\lib\site-packages\urllib3\util\retry.py", line 398, in increment
    raise MaxRetryError(_pool, url, error or ResponseError(cause))
urllib3.exceptions.MaxRetryError: HTTPSConnectionPool(host='www.amazon.co.jp', port=443): Max retries exceeded with url: /%E3%82%BD%E3%83%95%E3%83%88%E3%83%90%E3%83%B3%E3%82%AF%E3%82%BB%E3%83%AC%E3%82%AF%E3%82%B7%E3%83%A7%E3%83%B3-Bluetooth%E3%82%A4%E3%83%A4%E3%83%9B%E3%83%B3%EF%BC%88%E3%83%96%E3%83%A9%E3%83%83%E3%82%AF%EF%BC%89SoftBank-GLIDiC-SB-WS72-MRTW-BK/product-reviews/B07KNK8XCP/ref=sr_1_1?sortBy=recent&language=zh_CN (Caused by SSLError(SSLError("bad handshake: SysCallError(10054, 'WSAECONNRESET')")))

During handling of the above exception, another exception occurred:

Traceback (most recent call last):
  File "C:\Users\hhh\Desktop\Demo\reviews\amazon\amazon_review.py", line 232, in run
    review_html = self.parse_url(review_url)
  File "C:\Users\hhh\AppData\Local\Programs\Python\Python37\lib\site-packages\retrying.py", line 49, in wrapped_f
    return Retrying(*dargs, **dkw).call(f, *args, **kw)
  File "C:\Users\hhh\AppData\Local\Programs\Python\Python37\lib\site-packages\retrying.py", line 212, in call
    raise attempt.get()
  File "C:\Users\hhh\AppData\Local\Programs\Python\Python37\lib\site-packages\retrying.py", line 247, in get
    six.reraise(self.value[0], self.value[1], self.value[2])
  File "C:\Users\hhh\AppData\Local\Programs\Python\Python37\lib\site-packages\six.py", line 693, in reraise
    raise value
  File "C:\Users\hhh\AppData\Local\Programs\Python\Python37\lib\site-packages\retrying.py", line 200, in call
    attempt = Attempt(fn(*args, **kwargs), attempt_number, False)
  File "C:\Users\hhh\Desktop\Demo\reviews\amazon\amazon_review.py", line 40, in parse_url
    resp = requests.get(url, headers=self.headers, params=kw, timeout=100)
  File "C:\Users\hhh\AppData\Local\Programs\Python\Python37\lib\site-packages\requests\api.py", line 75, in get
    return request('get', url, params=params, **kwargs)
  File "C:\Users\hhh\AppData\Local\Programs\Python\Python37\lib\site-packages\requests\api.py", line 60, in request
    return session.request(method=method, url=url, **kwargs)
  File "C:\Users\hhh\AppData\Local\Programs\Python\Python37\lib\site-packages\requests\sessions.py", line 533, in request
    resp = self.send(prep, **send_kwargs)
  File "C:\Users\hhh\AppData\Local\Programs\Python\Python37\lib\site-packages\requests\sessions.py", line 646, in send
    r = adapter.send(request, **kwargs)
  File "C:\Users\hhh\AppData\Local\Programs\Python\Python37\lib\site-packages\requests\adapters.py", line 514, in send
    raise SSLError(e, request=request)
requests.exceptions.SSLError: HTTPSConnectionPool(host='www.amazon.co.jp', port=443): Max retries exceeded with url: /%E3%82%BD%E3%83%95%E3%83%88%E3%83%90%E3%83%B3%E3%82%AF%E3%82%BB%E3%83%AC%E3%82%AF%E3%82%B7%E3%83%A7%E3%83%B3-Bluetooth%E3%82%A4%E3%83%A4%E3%83%9B%E3%83%B3%EF%BC%88%E3%83%96%E3%83%A9%E3%83%83%E3%82%AF%EF%BC%89SoftBank-GLIDiC-SB-WS72-MRTW-BK/product-reviews/B07KNK8XCP/ref=sr_1_1?sortBy=recent&language=zh_CN (Caused by SSLError(SSLError("bad handshake: SysCallError(10054, 'WSAECONNRESET')")))
2019-07-09 17:08:06,692 - root - INFO - Amazon_end,耗时81.32646131515503秒
2019-07-09 17:08:11,913 - root - INFO - BestBuy,5368400共更新了0条
2019-07-09 17:08:17,454 - root - INFO - BestBuy,5892993共更新了0条
2019-07-09 17:08:20,063 - root - INFO - BestBuy,6349969共更新了0条,
2019-07-09 17:08:21,576 - root - INFO - BestBuy(6349969)获取评论主标签失败
2019-07-09 17:08:22,870 - root - INFO - BestBuy,6349969共更新了0条,
2019-07-09 17:08:22,874 - root - INFO - BestBuy,6349969共更新了0条,
2019-07-09 17:08:22,874 - root - INFO - BestBuy,6349969共更新了0条
2019-07-09 17:08:22,875 - root - INFO - BestBuy_end,耗时16.183716297149658秒
2019-07-09 17:08:23,470 - root - ERROR - JD(7438547)报错信息：数据库保存/更新失败
Traceback (most recent call last):
  File "C:\Users\hhh\Desktop\Demo\reviews\JD\jd_review.py", line 158, in save_data
    c.execute(sql)
cx_Oracle.IntegrityError: ORA-00001: 违反唯一约束条件 (EIP.ECOMMERCE_REVIEW_PIX3)
2019-07-09 17:08:23,476 - root - INFO - JD,https://item.jd.com/7438547.html共更新了0条,
2019-07-09 17:08:23,996 - root - ERROR - JD(8031600)报错信息：数据库保存/更新失败
Traceback (most recent call last):
  File "C:\Users\hhh\Desktop\Demo\reviews\JD\jd_review.py", line 158, in save_data
    c.execute(sql)
cx_Oracle.IntegrityError: ORA-00001: 违反唯一约束条件 (EIP.ECOMMERCE_REVIEW_PIX3)
2019-07-09 17:08:24,001 - root - INFO - JD,https://item.jd.com/8031600.html共更新了0条,
2019-07-09 17:08:24,637 - root - ERROR - JD(4298564)报错信息：数据库保存/更新失败
Traceback (most recent call last):
  File "C:\Users\hhh\Desktop\Demo\reviews\JD\jd_review.py", line 158, in save_data
    c.execute(sql)
cx_Oracle.IntegrityError: ORA-00001: 违反唯一约束条件 (EIP.ECOMMERCE_REVIEW_PIX3)
2019-07-09 17:08:24,642 - root - INFO - JD,https://item.jd.com/4298564.html共更新了1条,
2019-07-09 17:08:25,234 - root - ERROR - JD(100002501954)报错信息：数据库保存/更新失败
Traceback (most recent call last):
  File "C:\Users\hhh\Desktop\Demo\reviews\JD\jd_review.py", line 158, in save_data
    c.execute(sql)
cx_Oracle.IntegrityError: ORA-00001: 违反唯一约束条件 (EIP.ECOMMERCE_REVIEW_PIX3)
2019-07-09 17:08:25,238 - root - INFO - JD,https://item.jd.com/100002501954.html共更新了1条,
2019-07-09 17:08:25,790 - root - ERROR - JD(100001470134)报错信息：数据库保存/更新失败
Traceback (most recent call last):
  File "C:\Users\hhh\Desktop\Demo\reviews\JD\jd_review.py", line 158, in save_data
    c.execute(sql)
cx_Oracle.IntegrityError: ORA-00001: 违反唯一约束条件 (EIP.ECOMMERCE_REVIEW_PIX3)
2019-07-09 17:08:25,793 - root - INFO - JD,https://item.jd.com/100001470134.html共更新了6条,
2019-07-09 17:08:26,393 - root - ERROR - JD(34326476497)报错信息：数据库保存/更新失败
Traceback (most recent call last):
  File "C:\Users\hhh\Desktop\Demo\reviews\JD\jd_review.py", line 158, in save_data
    c.execute(sql)
cx_Oracle.IntegrityError: ORA-00001: 违反唯一约束条件 (EIP.ECOMMERCE_REVIEW_PIX3)
2019-07-09 17:08:26,398 - root - INFO - JD,https://item.jd.com/34326476497.html共更新了0条,
2019-07-09 17:08:26,984 - root - ERROR - JD(41014808466)报错信息：数据库保存/更新失败
Traceback (most recent call last):
  File "C:\Users\hhh\Desktop\Demo\reviews\JD\jd_review.py", line 158, in save_data
    c.execute(sql)
cx_Oracle.IntegrityError: ORA-00001: 违反唯一约束条件 (EIP.ECOMMERCE_REVIEW_PIX3)
2019-07-09 17:08:26,987 - root - INFO - JD,https://item.jd.com/41014808466.html共更新了2条,
2019-07-09 17:08:27,542 - root - ERROR - JD(2245024)报错信息：数据库保存/更新失败
Traceback (most recent call last):
  File "C:\Users\hhh\Desktop\Demo\reviews\JD\jd_review.py", line 158, in save_data
    c.execute(sql)
cx_Oracle.IntegrityError: ORA-00001: 违反唯一约束条件 (EIP.ECOMMERCE_REVIEW_PIX3)
2019-07-09 17:08:27,547 - root - INFO - JD,https://item.jd.com/2245024.html共更新了1条,
2019-07-09 17:08:28,704 - root - ERROR - JD(24818305875)报错信息：数据库保存/更新失败
Traceback (most recent call last):
  File "C:\Users\hhh\Desktop\Demo\reviews\JD\jd_review.py", line 158, in save_data
    c.execute(sql)
cx_Oracle.IntegrityError: ORA-00001: 违反唯一约束条件 (EIP.ECOMMERCE_REVIEW_PIX3)
2019-07-09 17:08:28,710 - root - INFO - JD,https://item.jd.com/24818305875.html共更新了0条,
2019-07-09 17:08:29,463 - root - ERROR - JD(46066831853)报错信息：数据库保存/更新失败
Traceback (most recent call last):
  File "C:\Users\hhh\Desktop\Demo\reviews\JD\jd_review.py", line 158, in save_data
    c.execute(sql)
cx_Oracle.IntegrityError: ORA-00001: 违反唯一约束条件 (EIP.ECOMMERCE_REVIEW_PIX3)
2019-07-09 17:08:29,470 - root - INFO - JD,https://item.jd.com/46066831853.html共更新了0条,
2019-07-09 17:08:41,691 - root - ERROR - JD(100001667527)报错信息：数据库保存/更新失败
Traceback (most recent call last):
  File "C:\Users\hhh\Desktop\Demo\reviews\JD\jd_review.py", line 158, in save_data
    c.execute(sql)
cx_Oracle.IntegrityError: ORA-00001: 违反唯一约束条件 (EIP.ECOMMERCE_REVIEW_PIX3)
2019-07-09 17:08:41,694 - root - INFO - JD,https://item.jd.com/100001667527.html共更新了29条,
2019-07-09 17:08:49,417 - root - ERROR - JD(100002361195)报错信息：数据库保存/更新失败
Traceback (most recent call last):
  File "C:\Users\hhh\Desktop\Demo\reviews\JD\jd_review.py", line 158, in save_data
    c.execute(sql)
cx_Oracle.IntegrityError: ORA-00001: 违反唯一约束条件 (EIP.ECOMMERCE_REVIEW_PIX3)
2019-07-09 17:08:49,419 - root - INFO - JD,https://item.jd.com/100002361195.html共更新了8条,
2019-07-09 17:08:49,420 - root - INFO - JD,耗时26.54400610923767秒
2019-07-09 17:09:22,549 - root - ERROR - tmall(528515320283)报错信息：第0条评论保存失败
Traceback (most recent call last):
  File "C:\Users\hhh\Desktop\Demo\reviews\TMALL\new_tmall.py", line 78, in get_content_list
    c.execute(sql_review)
cx_Oracle.IntegrityError: ORA-00001: 违反唯一约束条件 (EIP.ECOMMERCE_REVIEW_PIX3)
2019-07-09 17:09:22,618 - root - INFO - Tmall,528515320283共更新了0条,
2019-07-09 17:09:58,253 - root - ERROR - tmall(565187422922)报错信息：第0条评论保存失败
Traceback (most recent call last):
  File "C:\Users\hhh\Desktop\Demo\reviews\TMALL\new_tmall.py", line 78, in get_content_list
    c.execute(sql_review)
cx_Oracle.IntegrityError: ORA-00001: 违反唯一约束条件 (EIP.ECOMMERCE_REVIEW_PIX3)
2019-07-09 17:09:58,315 - root - INFO - Tmall,565187422922共更新了0条,
2019-07-09 17:10:47,862 - root - ERROR - tmall(552634156539)报错信息：第0条评论保存失败
Traceback (most recent call last):
  File "C:\Users\hhh\Desktop\Demo\reviews\TMALL\new_tmall.py", line 78, in get_content_list
    c.execute(sql_review)
cx_Oracle.IntegrityError: ORA-00001: 违反唯一约束条件 (EIP.ECOMMERCE_REVIEW_PIX3)
2019-07-09 17:10:47,933 - root - INFO - Tmall,552634156539共更新了0条,
2019-07-09 17:11:23,957 - root - ERROR - tmall(580233296207)报错信息：第1条评论保存失败
Traceback (most recent call last):
  File "C:\Users\hhh\Desktop\Demo\reviews\TMALL\new_tmall.py", line 78, in get_content_list
    c.execute(sql_review)
cx_Oracle.IntegrityError: ORA-00001: 违反唯一约束条件 (EIP.ECOMMERCE_REVIEW_PIX3)
2019-07-09 17:11:24,034 - root - ERROR - tmall(580233296207)报错信息：第1条评论保存失败
Traceback (most recent call last):
  File "C:\Users\hhh\Desktop\Demo\reviews\TMALL\new_tmall.py", line 78, in get_content_list
    c.execute(sql_review)
cx_Oracle.IntegrityError: ORA-00001: 违反唯一约束条件 (EIP.ECOMMERCE_REVIEW_PIX3)
2019-07-09 17:11:24,112 - root - ERROR - tmall(580233296207)报错信息：第1条评论保存失败
Traceback (most recent call last):
  File "C:\Users\hhh\Desktop\Demo\reviews\TMALL\new_tmall.py", line 78, in get_content_list
    c.execute(sql_review)
cx_Oracle.IntegrityError: ORA-00001: 违反唯一约束条件 (EIP.ECOMMERCE_REVIEW_PIX3)
2019-07-09 17:11:24,175 - root - INFO - Tmall,580233296207共更新了1条,
2019-07-09 17:12:07,905 - root - ERROR - tmall(574870586003)报错信息：第0条评论保存失败
Traceback (most recent call last):
  File "C:\Users\hhh\Desktop\Demo\reviews\TMALL\new_tmall.py", line 78, in get_content_list
    c.execute(sql_review)
cx_Oracle.IntegrityError: ORA-00001: 违反唯一约束条件 (EIP.ECOMMERCE_REVIEW_PIX3)
2019-07-09 17:12:07,971 - root - INFO - Tmall,574870586003共更新了0条,
2019-07-09 17:12:46,001 - root - ERROR - tmall(590865770191)报错信息：第18条评论保存失败
Traceback (most recent call last):
  File "C:\Users\hhh\Desktop\Demo\reviews\TMALL\new_tmall.py", line 78, in get_content_list
    c.execute(sql_review)
cx_Oracle.IntegrityError: ORA-00001: 违反唯一约束条件 (EIP.ECOMMERCE_REVIEW_PIX3)
2019-07-09 17:12:46,082 - root - ERROR - tmall(590865770191)报错信息：第18条评论保存失败
Traceback (most recent call last):
  File "C:\Users\hhh\Desktop\Demo\reviews\TMALL\new_tmall.py", line 78, in get_content_list
    c.execute(sql_review)
cx_Oracle.IntegrityError: ORA-00001: 违反唯一约束条件 (EIP.ECOMMERCE_REVIEW_PIX3)
2019-07-09 17:12:48,312 - root - ERROR - tmall(590865770191)报错信息：第18条评论保存失败
Traceback (most recent call last):
  File "C:\Users\hhh\Desktop\Demo\reviews\TMALL\new_tmall.py", line 78, in get_content_list
    c.execute(sql_review)
cx_Oracle.IntegrityError: ORA-00001: 违反唯一约束条件 (EIP.ECOMMERCE_REVIEW_PIX3)
2019-07-09 17:12:48,382 - root - ERROR - tmall(590865770191)报错信息：第18条评论保存失败
Traceback (most recent call last):
  File "C:\Users\hhh\Desktop\Demo\reviews\TMALL\new_tmall.py", line 78, in get_content_list
    c.execute(sql_review)
cx_Oracle.IntegrityError: ORA-00001: 违反唯一约束条件 (EIP.ECOMMERCE_REVIEW_PIX3)
2019-07-09 17:12:48,452 - root - ERROR - tmall(590865770191)报错信息：第18条评论保存失败
Traceback (most recent call last):
  File "C:\Users\hhh\Desktop\Demo\reviews\TMALL\new_tmall.py", line 78, in get_content_list
    c.execute(sql_review)
cx_Oracle.IntegrityError: ORA-00001: 违反唯一约束条件 (EIP.ECOMMERCE_REVIEW_PIX3)
2019-07-09 17:12:48,517 - root - ERROR - tmall(590865770191)报错信息：第18条评论保存失败
Traceback (most recent call last):
  File "C:\Users\hhh\Desktop\Demo\reviews\TMALL\new_tmall.py", line 78, in get_content_list
    c.execute(sql_review)
cx_Oracle.IntegrityError: ORA-00001: 违反唯一约束条件 (EIP.ECOMMERCE_REVIEW_PIX3)
2019-07-09 17:12:48,605 - root - ERROR - tmall(590865770191)报错信息：第18条评论保存失败
Traceback (most recent call last):
  File "C:\Users\hhh\Desktop\Demo\reviews\TMALL\new_tmall.py", line 78, in get_content_list
    c.execute(sql_review)
cx_Oracle.IntegrityError: ORA-00001: 违反唯一约束条件 (EIP.ECOMMERCE_REVIEW_PIX3)
2019-07-09 17:12:48,684 - root - ERROR - tmall(590865770191)报错信息：第18条评论保存失败
Traceback (most recent call last):
  File "C:\Users\hhh\Desktop\Demo\reviews\TMALL\new_tmall.py", line 78, in get_content_list
    c.execute(sql_review)
cx_Oracle.IntegrityError: ORA-00001: 违反唯一约束条件 (EIP.ECOMMERCE_REVIEW_PIX3)
2019-07-09 17:12:48,756 - root - ERROR - tmall(590865770191)报错信息：第18条评论保存失败
Traceback (most recent call last):
  File "C:\Users\hhh\Desktop\Demo\reviews\TMALL\new_tmall.py", line 78, in get_content_list
    c.execute(sql_review)
cx_Oracle.IntegrityError: ORA-00001: 违反唯一约束条件 (EIP.ECOMMERCE_REVIEW_PIX3)
2019-07-09 17:12:48,811 - root - ERROR - tmall(590865770191)报错信息：第18条评论保存失败
Traceback (most recent call last):
  File "C:\Users\hhh\Desktop\Demo\reviews\TMALL\new_tmall.py", line 78, in get_content_list
    c.execute(sql_review)
cx_Oracle.IntegrityError: ORA-00001: 违反唯一约束条件 (EIP.ECOMMERCE_REVIEW_PIX3)
2019-07-09 17:12:48,872 - root - ERROR - tmall(590865770191)报错信息：第18条评论保存失败
Traceback (most recent call last):
  File "C:\Users\hhh\Desktop\Demo\reviews\TMALL\new_tmall.py", line 78, in get_content_list
    c.execute(sql_review)
cx_Oracle.IntegrityError: ORA-00001: 违反唯一约束条件 (EIP.ECOMMERCE_REVIEW_PIX3)
2019-07-09 17:12:48,933 - root - ERROR - tmall(590865770191)报错信息：第18条评论保存失败
Traceback (most recent call last):
  File "C:\Users\hhh\Desktop\Demo\reviews\TMALL\new_tmall.py", line 78, in get_content_list
    c.execute(sql_review)
cx_Oracle.IntegrityError: ORA-00001: 违反唯一约束条件 (EIP.ECOMMERCE_REVIEW_PIX3)
2019-07-09 17:12:48,994 - root - ERROR - tmall(590865770191)报错信息：第18条评论保存失败
Traceback (most recent call last):
  File "C:\Users\hhh\Desktop\Demo\reviews\TMALL\new_tmall.py", line 78, in get_content_list
    c.execute(sql_review)
cx_Oracle.IntegrityError: ORA-00001: 违反唯一约束条件 (EIP.ECOMMERCE_REVIEW_PIX3)
2019-07-09 17:12:49,051 - root - ERROR - tmall(590865770191)报错信息：第18条评论保存失败
Traceback (most recent call last):
  File "C:\Users\hhh\Desktop\Demo\reviews\TMALL\new_tmall.py", line 78, in get_content_list
    c.execute(sql_review)
cx_Oracle.IntegrityError: ORA-00001: 违反唯一约束条件 (EIP.ECOMMERCE_REVIEW_PIX3)
2019-07-09 17:12:49,110 - root - ERROR - tmall(590865770191)报错信息：第18条评论保存失败
Traceback (most recent call last):
  File "C:\Users\hhh\Desktop\Demo\reviews\TMALL\new_tmall.py", line 78, in get_content_list
    c.execute(sql_review)
cx_Oracle.IntegrityError: ORA-00001: 违反唯一约束条件 (EIP.ECOMMERCE_REVIEW_PIX3)
2019-07-09 17:12:49,167 - root - ERROR - tmall(590865770191)报错信息：第18条评论保存失败
Traceback (most recent call last):
  File "C:\Users\hhh\Desktop\Demo\reviews\TMALL\new_tmall.py", line 78, in get_content_list
    c.execute(sql_review)
cx_Oracle.IntegrityError: ORA-00001: 违反唯一约束条件 (EIP.ECOMMERCE_REVIEW_PIX3)
2019-07-09 17:12:49,232 - root - ERROR - tmall(590865770191)报错信息：第18条评论保存失败
Traceback (most recent call last):
  File "C:\Users\hhh\Desktop\Demo\reviews\TMALL\new_tmall.py", line 78, in get_content_list
    c.execute(sql_review)
cx_Oracle.IntegrityError: ORA-00001: 违反唯一约束条件 (EIP.ECOMMERCE_REVIEW_PIX3)
2019-07-09 17:12:49,291 - root - ERROR - tmall(590865770191)报错信息：第18条评论保存失败
Traceback (most recent call last):
  File "C:\Users\hhh\Desktop\Demo\reviews\TMALL\new_tmall.py", line 78, in get_content_list
    c.execute(sql_review)
cx_Oracle.IntegrityError: ORA-00001: 违反唯一约束条件 (EIP.ECOMMERCE_REVIEW_PIX3)
2019-07-09 17:12:49,351 - root - ERROR - tmall(590865770191)报错信息：第18条评论保存失败
Traceback (most recent call last):
  File "C:\Users\hhh\Desktop\Demo\reviews\TMALL\new_tmall.py", line 78, in get_content_list
    c.execute(sql_review)
cx_Oracle.IntegrityError: ORA-00001: 违反唯一约束条件 (EIP.ECOMMERCE_REVIEW_PIX3)
2019-07-09 17:12:49,416 - root - ERROR - tmall(590865770191)报错信息：第18条评论保存失败
Traceback (most recent call last):
  File "C:\Users\hhh\Desktop\Demo\reviews\TMALL\new_tmall.py", line 78, in get_content_list
    c.execute(sql_review)
cx_Oracle.IntegrityError: ORA-00001: 违反唯一约束条件 (EIP.ECOMMERCE_REVIEW_PIX3)
2019-07-09 17:12:49,475 - root - ERROR - tmall(590865770191)报错信息：第18条评论保存失败
Traceback (most recent call last):
  File "C:\Users\hhh\Desktop\Demo\reviews\TMALL\new_tmall.py", line 78, in get_content_list
    c.execute(sql_review)
cx_Oracle.IntegrityError: ORA-00001: 违反唯一约束条件 (EIP.ECOMMERCE_REVIEW_PIX3)
2019-07-09 17:12:49,541 - root - ERROR - tmall(590865770191)报错信息：第18条评论保存失败
Traceback (most recent call last):
  File "C:\Users\hhh\Desktop\Demo\reviews\TMALL\new_tmall.py", line 78, in get_content_list
    c.execute(sql_review)
cx_Oracle.IntegrityError: ORA-00001: 违反唯一约束条件 (EIP.ECOMMERCE_REVIEW_PIX3)
2019-07-09 17:12:51,788 - root - ERROR - tmall(590865770191)报错信息：第18条评论保存失败
Traceback (most recent call last):
  File "C:\Users\hhh\Desktop\Demo\reviews\TMALL\new_tmall.py", line 78, in get_content_list
    c.execute(sql_review)
cx_Oracle.IntegrityError: ORA-00001: 违反唯一约束条件 (EIP.ECOMMERCE_REVIEW_PIX3)
2019-07-09 17:12:51,856 - root - INFO - Tmall,590865770191共更新了18条,
2019-07-09 17:12:53,924 - root - INFO - tmall_end,耗时244.50358629226685秒
